============================= test session starts ==============================
platform darwin -- Python 3.11.6, pytest-7.4.3, pluggy-1.6.0
rootdir: /Users/rafal.lagowski/ProjectsRL/gen-projects/project-generator-cli/templates/common/backend
configfile: pyproject.toml
testpaths: tests
plugins: httpx-0.26.0, asyncio-0.21.1, anyio-3.7.1
asyncio: mode=Mode.STRICT
collected 78 items

tests/test_admin.py FEEEEEEEEEEEEE                                       [ 17%]
tests/test_auth.py ......FFF..sssssEEEEEEEE                              [ 48%]
tests/test_models.py .........                                           [ 60%]
tests/test_schemas.py ...F...F.F                                         [ 73%]
tests/test_users.py EEEEEEEEEEEEEEEEEEEEE                                [100%]

==================================== ERRORS ====================================
__ ERROR at setup of TestAdminDashboard.test_get_system_stats_as_regular_user __
E   RuntimeError: Task <Task pending name='anyio.from_thread.BlockingPortal._call_func' coro=<BlockingPortal._call_func() running at /Users/rafal.lagowski/ProjectsRL/gen-projects/project-generator-cli/templates/common/backend/venv/lib/python3.11/site-packages/anyio/from_thread.py:217> cb=[TaskGroup._spawn.<locals>.task_done() at /Users/rafal.lagowski/ProjectsRL/gen-projects/project-generator-cli/templates/common/backend/venv/lib/python3.11/site-packages/anyio/_backends/_asyncio.py:661]> got Future <Future pending cb=[Protocol._on_waiter_completed()]> attached to a different loop
---------------------------- Captured stdout setup -----------------------------
ðŸš€ Starting StackWizard Backend...
2025-08-19 14:48:22,451 INFO sqlalchemy.engine.Engine BEGIN (implicit)
2025-08-19 14:48:22,452 INFO sqlalchemy.engine.Engine SELECT users.id, users.email, users.hashed_password, users.username, users.full_name, users.is_active, users.is_superuser, users.is_verified, users.password_reset_token, users.password_reset_at, users.email_verification_token, users.email_verified_at, users.last_login_at, users.login_count, users.created_at, users.updated_at 
FROM users 
WHERE users.is_superuser = true
2025-08-19 14:48:22,452 INFO sqlalchemy.engine.Engine [cached since 0.9173s ago] ()
2025-08-19 14:48:22,452 INFO sqlalchemy.engine.Engine ROLLBACK
------------------------------ Captured log setup ------------------------------
INFO     sqlalchemy.engine.Engine:base.py:2689 BEGIN (implicit)
INFO     sqlalchemy.engine.Engine:base.py:1848 SELECT users.id, users.email, users.hashed_password, users.username, users.full_name, users.is_active, users.is_superuser, users.is_verified, users.password_reset_token, users.password_reset_at, users.email_verification_token, users.email_verified_at, users.last_login_at, users.login_count, users.created_at, users.updated_at 
FROM users 
WHERE users.is_superuser = true
INFO     sqlalchemy.engine.Engine:base.py:1848 [cached since 0.9173s ago] ()
INFO     sqlalchemy.engine.Engine:base.py:2692 ROLLBACK
______ ERROR at setup of TestAdminDashboard.test_get_recent_registrations ______
E   asyncpg.exceptions._base.InterfaceError: cannot perform operation: another operation is in progress

The above exception was the direct cause of the following exception:
E   sqlalchemy.dialects.postgresql.asyncpg.AsyncAdapt_asyncpg_dbapi.InterfaceError: <class 'asyncpg.exceptions._base.InterfaceError'>: cannot perform operation: another operation is in progress

The above exception was the direct cause of the following exception:
E   sqlalchemy.exc.InterfaceError: (sqlalchemy.dialects.postgresql.asyncpg.InterfaceError) <class 'asyncpg.exceptions._base.InterfaceError'>: cannot perform operation: another operation is in progress
    [SQL: SELECT users.id, users.email, users.hashed_password, users.username, users.full_name, users.is_active, users.is_superuser, users.is_verified, users.password_reset_token, users.password_reset_at, users.email_verification_token, users.email_verified_at, users.last_login_at, users.login_count, users.created_at, users.updated_at 
    FROM users 
    WHERE users.is_superuser = true]
    (Background on this error at: https://sqlalche.me/e/20/rvf5)
---------------------------- Captured stdout setup -----------------------------
ðŸš€ Starting StackWizard Backend...
2025-08-19 14:48:22,503 INFO sqlalchemy.engine.Engine BEGIN (implicit)
2025-08-19 14:48:22,503 INFO sqlalchemy.engine.Engine SELECT users.id, users.email, users.hashed_password, users.username, users.full_name, users.is_active, users.is_superuser, users.is_verified, users.password_reset_token, users.password_reset_at, users.email_verification_token, users.email_verified_at, users.last_login_at, users.login_count, users.created_at, users.updated_at 
FROM users 
WHERE users.is_superuser = true
2025-08-19 14:48:22,503 INFO sqlalchemy.engine.Engine [cached since 0.969s ago] ()
2025-08-19 14:48:22,504 INFO sqlalchemy.engine.Engine ROLLBACK
------------------------------ Captured log setup ------------------------------
INFO     sqlalchemy.engine.Engine:base.py:2689 BEGIN (implicit)
INFO     sqlalchemy.engine.Engine:base.py:1848 SELECT users.id, users.email, users.hashed_password, users.username, users.full_name, users.is_active, users.is_superuser, users.is_verified, users.password_reset_token, users.password_reset_at, users.email_verification_token, users.email_verified_at, users.last_login_at, users.login_count, users.created_at, users.updated_at 
FROM users 
WHERE users.is_superuser = true
INFO     sqlalchemy.engine.Engine:base.py:1848 [cached since 0.969s ago] ()
INFO     sqlalchemy.engine.Engine:base.py:2692 ROLLBACK
_______ ERROR at setup of TestAdminDashboard.test_search_users_by_email ________
E   asyncpg.exceptions._base.InterfaceError: cannot perform operation: another operation is in progress

The above exception was the direct cause of the following exception:
E   sqlalchemy.dialects.postgresql.asyncpg.AsyncAdapt_asyncpg_dbapi.InterfaceError: <class 'asyncpg.exceptions._base.InterfaceError'>: cannot perform operation: another operation is in progress

The above exception was the direct cause of the following exception:
E   sqlalchemy.exc.InterfaceError: (sqlalchemy.dialects.postgresql.asyncpg.InterfaceError) <class 'asyncpg.exceptions._base.InterfaceError'>: cannot perform operation: another operation is in progress
    [SQL: SELECT users.id, users.email, users.hashed_password, users.username, users.full_name, users.is_active, users.is_superuser, users.is_verified, users.password_reset_token, users.password_reset_at, users.email_verification_token, users.email_verified_at, users.last_login_at, users.login_count, users.created_at, users.updated_at 
    FROM users 
    WHERE users.is_superuser = true]
    (Background on this error at: https://sqlalche.me/e/20/rvf5)
---------------------------- Captured stdout setup -----------------------------
ðŸš€ Starting StackWizard Backend...
2025-08-19 14:48:22,530 INFO sqlalchemy.engine.Engine BEGIN (implicit)
2025-08-19 14:48:22,530 INFO sqlalchemy.engine.Engine SELECT users.id, users.email, users.hashed_password, users.username, users.full_name, users.is_active, users.is_superuser, users.is_verified, users.password_reset_token, users.password_reset_at, users.email_verification_token, users.email_verified_at, users.last_login_at, users.login_count, users.created_at, users.updated_at 
FROM users 
WHERE users.is_superuser = true
2025-08-19 14:48:22,530 INFO sqlalchemy.engine.Engine [cached since 0.9956s ago] ()
2025-08-19 14:48:22,530 INFO sqlalchemy.engine.Engine ROLLBACK
------------------------------ Captured log setup ------------------------------
INFO     sqlalchemy.engine.Engine:base.py:2689 BEGIN (implicit)
INFO     sqlalchemy.engine.Engine:base.py:1848 SELECT users.id, users.email, users.hashed_password, users.username, users.full_name, users.is_active, users.is_superuser, users.is_verified, users.password_reset_token, users.password_reset_at, users.email_verification_token, users.email_verified_at, users.last_login_at, users.login_count, users.created_at, users.updated_at 
FROM users 
WHERE users.is_superuser = true
INFO     sqlalchemy.engine.Engine:base.py:1848 [cached since 0.9956s ago] ()
INFO     sqlalchemy.engine.Engine:base.py:2692 ROLLBACK
________ ERROR at setup of TestAdminDashboard.test_bulk_activate_users _________
E   asyncpg.exceptions._base.InterfaceError: cannot perform operation: another operation is in progress

The above exception was the direct cause of the following exception:
E   sqlalchemy.dialects.postgresql.asyncpg.AsyncAdapt_asyncpg_dbapi.InterfaceError: <class 'asyncpg.exceptions._base.InterfaceError'>: cannot perform operation: another operation is in progress

The above exception was the direct cause of the following exception:
E   sqlalchemy.exc.InterfaceError: (sqlalchemy.dialects.postgresql.asyncpg.InterfaceError) <class 'asyncpg.exceptions._base.InterfaceError'>: cannot perform operation: another operation is in progress
    [SQL: SELECT users.id, users.email, users.hashed_password, users.username, users.full_name, users.is_active, users.is_superuser, users.is_verified, users.password_reset_token, users.password_reset_at, users.email_verification_token, users.email_verified_at, users.last_login_at, users.login_count, users.created_at, users.updated_at 
    FROM users 
    WHERE users.is_superuser = true]
    (Background on this error at: https://sqlalche.me/e/20/rvf5)
---------------------------- Captured stdout setup -----------------------------
ðŸš€ Starting StackWizard Backend...
2025-08-19 14:48:22,557 INFO sqlalchemy.engine.Engine BEGIN (implicit)
2025-08-19 14:48:22,557 INFO sqlalchemy.engine.Engine SELECT users.id, users.email, users.hashed_password, users.username, users.full_name, users.is_active, users.is_superuser, users.is_verified, users.password_reset_token, users.password_reset_at, users.email_verification_token, users.email_verified_at, users.last_login_at, users.login_count, users.created_at, users.updated_at 
FROM users 
WHERE users.is_superuser = true
2025-08-19 14:48:22,558 INFO sqlalchemy.engine.Engine [cached since 1.023s ago] ()
2025-08-19 14:48:22,558 INFO sqlalchemy.engine.Engine ROLLBACK
------------------------------ Captured log setup ------------------------------
INFO     sqlalchemy.engine.Engine:base.py:2689 BEGIN (implicit)
INFO     sqlalchemy.engine.Engine:base.py:1848 SELECT users.id, users.email, users.hashed_password, users.username, users.full_name, users.is_active, users.is_superuser, users.is_verified, users.password_reset_token, users.password_reset_at, users.email_verification_token, users.email_verified_at, users.last_login_at, users.login_count, users.created_at, users.updated_at 
FROM users 
WHERE users.is_superuser = true
INFO     sqlalchemy.engine.Engine:base.py:1848 [cached since 1.023s ago] ()
INFO     sqlalchemy.engine.Engine:base.py:2692 ROLLBACK
_______ ERROR at setup of TestAdminDashboard.test_bulk_deactivate_users ________
E   asyncpg.exceptions._base.InterfaceError: cannot perform operation: another operation is in progress

The above exception was the direct cause of the following exception:
E   sqlalchemy.dialects.postgresql.asyncpg.AsyncAdapt_asyncpg_dbapi.InterfaceError: <class 'asyncpg.exceptions._base.InterfaceError'>: cannot perform operation: another operation is in progress

The above exception was the direct cause of the following exception:
E   sqlalchemy.exc.InterfaceError: (sqlalchemy.dialects.postgresql.asyncpg.InterfaceError) <class 'asyncpg.exceptions._base.InterfaceError'>: cannot perform operation: another operation is in progress
    [SQL: SELECT users.id, users.email, users.hashed_password, users.username, users.full_name, users.is_active, users.is_superuser, users.is_verified, users.password_reset_token, users.password_reset_at, users.email_verification_token, users.email_verified_at, users.last_login_at, users.login_count, users.created_at, users.updated_at 
    FROM users 
    WHERE users.is_superuser = true]
    (Background on this error at: https://sqlalche.me/e/20/rvf5)
---------------------------- Captured stdout setup -----------------------------
ðŸš€ Starting StackWizard Backend...
2025-08-19 14:48:22,589 INFO sqlalchemy.engine.Engine BEGIN (implicit)
2025-08-19 14:48:22,589 INFO sqlalchemy.engine.Engine SELECT users.id, users.email, users.hashed_password, users.username, users.full_name, users.is_active, users.is_superuser, users.is_verified, users.password_reset_token, users.password_reset_at, users.email_verification_token, users.email_verified_at, users.last_login_at, users.login_count, users.created_at, users.updated_at 
FROM users 
WHERE users.is_superuser = true
2025-08-19 14:48:22,589 INFO sqlalchemy.engine.Engine [cached since 1.055s ago] ()
2025-08-19 14:48:22,589 INFO sqlalchemy.engine.Engine ROLLBACK
------------------------------ Captured log setup ------------------------------
INFO     sqlalchemy.engine.Engine:base.py:2689 BEGIN (implicit)
INFO     sqlalchemy.engine.Engine:base.py:1848 SELECT users.id, users.email, users.hashed_password, users.username, users.full_name, users.is_active, users.is_superuser, users.is_verified, users.password_reset_token, users.password_reset_at, users.email_verification_token, users.email_verified_at, users.last_login_at, users.login_count, users.created_at, users.updated_at 
FROM users 
WHERE users.is_superuser = true
INFO     sqlalchemy.engine.Engine:base.py:1848 [cached since 1.055s ago] ()
INFO     sqlalchemy.engine.Engine:base.py:2692 ROLLBACK
__________ ERROR at setup of TestAdminAuditLog.test_log_admin_action ___________
E   asyncpg.exceptions._base.InterfaceError: cannot perform operation: another operation is in progress

The above exception was the direct cause of the following exception:
E   sqlalchemy.dialects.postgresql.asyncpg.AsyncAdapt_asyncpg_dbapi.InterfaceError: <class 'asyncpg.exceptions._base.InterfaceError'>: cannot perform operation: another operation is in progress

The above exception was the direct cause of the following exception:
E   sqlalchemy.exc.InterfaceError: (sqlalchemy.dialects.postgresql.asyncpg.InterfaceError) <class 'asyncpg.exceptions._base.InterfaceError'>: cannot perform operation: another operation is in progress
    [SQL: SELECT users.id, users.email, users.hashed_password, users.username, users.full_name, users.is_active, users.is_superuser, users.is_verified, users.password_reset_token, users.password_reset_at, users.email_verification_token, users.email_verified_at, users.last_login_at, users.login_count, users.created_at, users.updated_at 
    FROM users 
    WHERE users.is_superuser = true]
    (Background on this error at: https://sqlalche.me/e/20/rvf5)
---------------------------- Captured stdout setup -----------------------------
ðŸš€ Starting StackWizard Backend...
2025-08-19 14:48:22,615 INFO sqlalchemy.engine.Engine BEGIN (implicit)
2025-08-19 14:48:22,615 INFO sqlalchemy.engine.Engine SELECT users.id, users.email, users.hashed_password, users.username, users.full_name, users.is_active, users.is_superuser, users.is_verified, users.password_reset_token, users.password_reset_at, users.email_verification_token, users.email_verified_at, users.last_login_at, users.login_count, users.created_at, users.updated_at 
FROM users 
WHERE users.is_superuser = true
2025-08-19 14:48:22,615 INFO sqlalchemy.engine.Engine [cached since 1.081s ago] ()
2025-08-19 14:48:22,616 INFO sqlalchemy.engine.Engine ROLLBACK
------------------------------ Captured log setup ------------------------------
INFO     sqlalchemy.engine.Engine:base.py:2689 BEGIN (implicit)
INFO     sqlalchemy.engine.Engine:base.py:1848 SELECT users.id, users.email, users.hashed_password, users.username, users.full_name, users.is_active, users.is_superuser, users.is_verified, users.password_reset_token, users.password_reset_at, users.email_verification_token, users.email_verified_at, users.last_login_at, users.login_count, users.created_at, users.updated_at 
FROM users 
WHERE users.is_superuser = true
INFO     sqlalchemy.engine.Engine:base.py:1848 [cached since 1.081s ago] ()
INFO     sqlalchemy.engine.Engine:base.py:2692 ROLLBACK
_ ERROR at setup of TestAdminAuditLog.test_audit_log_access_denied_for_regular_user _
E   asyncpg.exceptions._base.InterfaceError: cannot perform operation: another operation is in progress

The above exception was the direct cause of the following exception:
E   sqlalchemy.dialects.postgresql.asyncpg.AsyncAdapt_asyncpg_dbapi.InterfaceError: <class 'asyncpg.exceptions._base.InterfaceError'>: cannot perform operation: another operation is in progress

The above exception was the direct cause of the following exception:
E   sqlalchemy.exc.InterfaceError: (sqlalchemy.dialects.postgresql.asyncpg.InterfaceError) <class 'asyncpg.exceptions._base.InterfaceError'>: cannot perform operation: another operation is in progress
    [SQL: SELECT users.id, users.email, users.hashed_password, users.username, users.full_name, users.is_active, users.is_superuser, users.is_verified, users.password_reset_token, users.password_reset_at, users.email_verification_token, users.email_verified_at, users.last_login_at, users.login_count, users.created_at, users.updated_at 
    FROM users 
    WHERE users.is_superuser = true]
    (Background on this error at: https://sqlalche.me/e/20/rvf5)
---------------------------- Captured stdout setup -----------------------------
ðŸš€ Starting StackWizard Backend...
2025-08-19 14:48:22,642 INFO sqlalchemy.engine.Engine BEGIN (implicit)
2025-08-19 14:48:22,642 INFO sqlalchemy.engine.Engine SELECT users.id, users.email, users.hashed_password, users.username, users.full_name, users.is_active, users.is_superuser, users.is_verified, users.password_reset_token, users.password_reset_at, users.email_verification_token, users.email_verified_at, users.last_login_at, users.login_count, users.created_at, users.updated_at 
FROM users 
WHERE users.is_superuser = true
2025-08-19 14:48:22,642 INFO sqlalchemy.engine.Engine [cached since 1.108s ago] ()
2025-08-19 14:48:22,642 INFO sqlalchemy.engine.Engine ROLLBACK
------------------------------ Captured log setup ------------------------------
INFO     sqlalchemy.engine.Engine:base.py:2689 BEGIN (implicit)
INFO     sqlalchemy.engine.Engine:base.py:1848 SELECT users.id, users.email, users.hashed_password, users.username, users.full_name, users.is_active, users.is_superuser, users.is_verified, users.password_reset_token, users.password_reset_at, users.email_verification_token, users.email_verified_at, users.last_login_at, users.login_count, users.created_at, users.updated_at 
FROM users 
WHERE users.is_superuser = true
INFO     sqlalchemy.engine.Engine:base.py:1848 [cached since 1.108s ago] ()
INFO     sqlalchemy.engine.Engine:base.py:2692 ROLLBACK
___ ERROR at setup of TestAdminUserManagement.test_admin_reset_user_password ___
E   asyncpg.exceptions._base.InterfaceError: cannot perform operation: another operation is in progress

The above exception was the direct cause of the following exception:
E   sqlalchemy.dialects.postgresql.asyncpg.AsyncAdapt_asyncpg_dbapi.InterfaceError: <class 'asyncpg.exceptions._base.InterfaceError'>: cannot perform operation: another operation is in progress

The above exception was the direct cause of the following exception:
E   sqlalchemy.exc.InterfaceError: (sqlalchemy.dialects.postgresql.asyncpg.InterfaceError) <class 'asyncpg.exceptions._base.InterfaceError'>: cannot perform operation: another operation is in progress
    [SQL: SELECT users.id, users.email, users.hashed_password, users.username, users.full_name, users.is_active, users.is_superuser, users.is_verified, users.password_reset_token, users.password_reset_at, users.email_verification_token, users.email_verified_at, users.last_login_at, users.login_count, users.created_at, users.updated_at 
    FROM users 
    WHERE users.is_superuser = true]
    (Background on this error at: https://sqlalche.me/e/20/rvf5)
---------------------------- Captured stdout setup -----------------------------
ðŸš€ Starting StackWizard Backend...
2025-08-19 14:48:22,672 INFO sqlalchemy.engine.Engine BEGIN (implicit)
2025-08-19 14:48:22,673 INFO sqlalchemy.engine.Engine SELECT users.id, users.email, users.hashed_password, users.username, users.full_name, users.is_active, users.is_superuser, users.is_verified, users.password_reset_token, users.password_reset_at, users.email_verification_token, users.email_verified_at, users.last_login_at, users.login_count, users.created_at, users.updated_at 
FROM users 
WHERE users.is_superuser = true
2025-08-19 14:48:22,673 INFO sqlalchemy.engine.Engine [cached since 1.138s ago] ()
2025-08-19 14:48:22,673 INFO sqlalchemy.engine.Engine ROLLBACK
------------------------------ Captured log setup ------------------------------
INFO     sqlalchemy.engine.Engine:base.py:2689 BEGIN (implicit)
INFO     sqlalchemy.engine.Engine:base.py:1848 SELECT users.id, users.email, users.hashed_password, users.username, users.full_name, users.is_active, users.is_superuser, users.is_verified, users.password_reset_token, users.password_reset_at, users.email_verification_token, users.email_verified_at, users.last_login_at, users.login_count, users.created_at, users.updated_at 
FROM users 
WHERE users.is_superuser = true
INFO     sqlalchemy.engine.Engine:base.py:1848 [cached since 1.138s ago] ()
INFO     sqlalchemy.engine.Engine:base.py:2692 ROLLBACK
____ ERROR at setup of TestAdminUserManagement.test_admin_verify_user_email ____
E   asyncpg.exceptions._base.InterfaceError: cannot perform operation: another operation is in progress

The above exception was the direct cause of the following exception:
E   sqlalchemy.dialects.postgresql.asyncpg.AsyncAdapt_asyncpg_dbapi.InterfaceError: <class 'asyncpg.exceptions._base.InterfaceError'>: cannot perform operation: another operation is in progress

The above exception was the direct cause of the following exception:
E   sqlalchemy.exc.InterfaceError: (sqlalchemy.dialects.postgresql.asyncpg.InterfaceError) <class 'asyncpg.exceptions._base.InterfaceError'>: cannot perform operation: another operation is in progress
    [SQL: SELECT users.id, users.email, users.hashed_password, users.username, users.full_name, users.is_active, users.is_superuser, users.is_verified, users.password_reset_token, users.password_reset_at, users.email_verification_token, users.email_verified_at, users.last_login_at, users.login_count, users.created_at, users.updated_at 
    FROM users 
    WHERE users.is_superuser = true]
    (Background on this error at: https://sqlalche.me/e/20/rvf5)
---------------------------- Captured stdout setup -----------------------------
ðŸš€ Starting StackWizard Backend...
2025-08-19 14:48:22,699 INFO sqlalchemy.engine.Engine BEGIN (implicit)
2025-08-19 14:48:22,699 INFO sqlalchemy.engine.Engine SELECT users.id, users.email, users.hashed_password, users.username, users.full_name, users.is_active, users.is_superuser, users.is_verified, users.password_reset_token, users.password_reset_at, users.email_verification_token, users.email_verified_at, users.last_login_at, users.login_count, users.created_at, users.updated_at 
FROM users 
WHERE users.is_superuser = true
2025-08-19 14:48:22,699 INFO sqlalchemy.engine.Engine [cached since 1.164s ago] ()
2025-08-19 14:48:22,699 INFO sqlalchemy.engine.Engine ROLLBACK
------------------------------ Captured log setup ------------------------------
INFO     sqlalchemy.engine.Engine:base.py:2689 BEGIN (implicit)
INFO     sqlalchemy.engine.Engine:base.py:1848 SELECT users.id, users.email, users.hashed_password, users.username, users.full_name, users.is_active, users.is_superuser, users.is_verified, users.password_reset_token, users.password_reset_at, users.email_verification_token, users.email_verified_at, users.last_login_at, users.login_count, users.created_at, users.updated_at 
FROM users 
WHERE users.is_superuser = true
INFO     sqlalchemy.engine.Engine:base.py:1848 [cached since 1.164s ago] ()
INFO     sqlalchemy.engine.Engine:base.py:2692 ROLLBACK
______ ERROR at setup of TestAdminUserManagement.test_admin_export_users _______
E   asyncpg.exceptions._base.InterfaceError: cannot perform operation: another operation is in progress

The above exception was the direct cause of the following exception:
E   sqlalchemy.dialects.postgresql.asyncpg.AsyncAdapt_asyncpg_dbapi.InterfaceError: <class 'asyncpg.exceptions._base.InterfaceError'>: cannot perform operation: another operation is in progress

The above exception was the direct cause of the following exception:
E   sqlalchemy.exc.InterfaceError: (sqlalchemy.dialects.postgresql.asyncpg.InterfaceError) <class 'asyncpg.exceptions._base.InterfaceError'>: cannot perform operation: another operation is in progress
    [SQL: SELECT users.id, users.email, users.hashed_password, users.username, users.full_name, users.is_active, users.is_superuser, users.is_verified, users.password_reset_token, users.password_reset_at, users.email_verification_token, users.email_verified_at, users.last_login_at, users.login_count, users.created_at, users.updated_at 
    FROM users 
    WHERE users.is_superuser = true]
    (Background on this error at: https://sqlalche.me/e/20/rvf5)
---------------------------- Captured stdout setup -----------------------------
ðŸš€ Starting StackWizard Backend...
2025-08-19 14:48:22,731 INFO sqlalchemy.engine.Engine BEGIN (implicit)
2025-08-19 14:48:22,731 INFO sqlalchemy.engine.Engine SELECT users.id, users.email, users.hashed_password, users.username, users.full_name, users.is_active, users.is_superuser, users.is_verified, users.password_reset_token, users.password_reset_at, users.email_verification_token, users.email_verified_at, users.last_login_at, users.login_count, users.created_at, users.updated_at 
FROM users 
WHERE users.is_superuser = true
2025-08-19 14:48:22,731 INFO sqlalchemy.engine.Engine [cached since 1.197s ago] ()
2025-08-19 14:48:22,731 INFO sqlalchemy.engine.Engine ROLLBACK
------------------------------ Captured log setup ------------------------------
INFO     sqlalchemy.engine.Engine:base.py:2689 BEGIN (implicit)
INFO     sqlalchemy.engine.Engine:base.py:1848 SELECT users.id, users.email, users.hashed_password, users.username, users.full_name, users.is_active, users.is_superuser, users.is_verified, users.password_reset_token, users.password_reset_at, users.email_verification_token, users.email_verified_at, users.last_login_at, users.login_count, users.created_at, users.updated_at 
FROM users 
WHERE users.is_superuser = true
INFO     sqlalchemy.engine.Engine:base.py:1848 [cached since 1.197s ago] ()
INFO     sqlalchemy.engine.Engine:base.py:2692 ROLLBACK
______ ERROR at setup of TestAdminUserManagement.test_admin_import_users _______
E   asyncpg.exceptions._base.InterfaceError: cannot perform operation: another operation is in progress

The above exception was the direct cause of the following exception:
E   sqlalchemy.dialects.postgresql.asyncpg.AsyncAdapt_asyncpg_dbapi.InterfaceError: <class 'asyncpg.exceptions._base.InterfaceError'>: cannot perform operation: another operation is in progress

The above exception was the direct cause of the following exception:
E   sqlalchemy.exc.InterfaceError: (sqlalchemy.dialects.postgresql.asyncpg.InterfaceError) <class 'asyncpg.exceptions._base.InterfaceError'>: cannot perform operation: another operation is in progress
    [SQL: SELECT users.id, users.email, users.hashed_password, users.username, users.full_name, users.is_active, users.is_superuser, users.is_verified, users.password_reset_token, users.password_reset_at, users.email_verification_token, users.email_verified_at, users.last_login_at, users.login_count, users.created_at, users.updated_at 
    FROM users 
    WHERE users.is_superuser = true]
    (Background on this error at: https://sqlalche.me/e/20/rvf5)
---------------------------- Captured stdout setup -----------------------------
ðŸš€ Starting StackWizard Backend...
2025-08-19 14:48:22,760 INFO sqlalchemy.engine.Engine BEGIN (implicit)
2025-08-19 14:48:22,760 INFO sqlalchemy.engine.Engine SELECT users.id, users.email, users.hashed_password, users.username, users.full_name, users.is_active, users.is_superuser, users.is_verified, users.password_reset_token, users.password_reset_at, users.email_verification_token, users.email_verified_at, users.last_login_at, users.login_count, users.created_at, users.updated_at 
FROM users 
WHERE users.is_superuser = true
2025-08-19 14:48:22,760 INFO sqlalchemy.engine.Engine [cached since 1.225s ago] ()
2025-08-19 14:48:22,760 INFO sqlalchemy.engine.Engine ROLLBACK
------------------------------ Captured log setup ------------------------------
INFO     sqlalchemy.engine.Engine:base.py:2689 BEGIN (implicit)
INFO     sqlalchemy.engine.Engine:base.py:1848 SELECT users.id, users.email, users.hashed_password, users.username, users.full_name, users.is_active, users.is_superuser, users.is_verified, users.password_reset_token, users.password_reset_at, users.email_verification_token, users.email_verified_at, users.last_login_at, users.login_count, users.created_at, users.updated_at 
FROM users 
WHERE users.is_superuser = true
INFO     sqlalchemy.engine.Engine:base.py:1848 [cached since 1.225s ago] ()
INFO     sqlalchemy.engine.Engine:base.py:2692 ROLLBACK
____ ERROR at setup of TestAdminUserManagement.test_admin_get_user_sessions ____
E   asyncpg.exceptions._base.InterfaceError: cannot perform operation: another operation is in progress

The above exception was the direct cause of the following exception:
E   sqlalchemy.dialects.postgresql.asyncpg.AsyncAdapt_asyncpg_dbapi.InterfaceError: <class 'asyncpg.exceptions._base.InterfaceError'>: cannot perform operation: another operation is in progress

The above exception was the direct cause of the following exception:
E   sqlalchemy.exc.InterfaceError: (sqlalchemy.dialects.postgresql.asyncpg.InterfaceError) <class 'asyncpg.exceptions._base.InterfaceError'>: cannot perform operation: another operation is in progress
    [SQL: SELECT users.id, users.email, users.hashed_password, users.username, users.full_name, users.is_active, users.is_superuser, users.is_verified, users.password_reset_token, users.password_reset_at, users.email_verification_token, users.email_verified_at, users.last_login_at, users.login_count, users.created_at, users.updated_at 
    FROM users 
    WHERE users.is_superuser = true]
    (Background on this error at: https://sqlalche.me/e/20/rvf5)
---------------------------- Captured stdout setup -----------------------------
ðŸš€ Starting StackWizard Backend...
2025-08-19 14:48:22,787 INFO sqlalchemy.engine.Engine BEGIN (implicit)
2025-08-19 14:48:22,787 INFO sqlalchemy.engine.Engine SELECT users.id, users.email, users.hashed_password, users.username, users.full_name, users.is_active, users.is_superuser, users.is_verified, users.password_reset_token, users.password_reset_at, users.email_verification_token, users.email_verified_at, users.last_login_at, users.login_count, users.created_at, users.updated_at 
FROM users 
WHERE users.is_superuser = true
2025-08-19 14:48:22,787 INFO sqlalchemy.engine.Engine [cached since 1.253s ago] ()
2025-08-19 14:48:22,787 INFO sqlalchemy.engine.Engine ROLLBACK
------------------------------ Captured log setup ------------------------------
INFO     sqlalchemy.engine.Engine:base.py:2689 BEGIN (implicit)
INFO     sqlalchemy.engine.Engine:base.py:1848 SELECT users.id, users.email, users.hashed_password, users.username, users.full_name, users.is_active, users.is_superuser, users.is_verified, users.password_reset_token, users.password_reset_at, users.email_verification_token, users.email_verified_at, users.last_login_at, users.login_count, users.created_at, users.updated_at 
FROM users 
WHERE users.is_superuser = true
INFO     sqlalchemy.engine.Engine:base.py:1848 [cached since 1.253s ago] ()
INFO     sqlalchemy.engine.Engine:base.py:2692 ROLLBACK
__ ERROR at setup of TestAdminUserManagement.test_admin_revoke_user_sessions ___
E   asyncpg.exceptions._base.InterfaceError: cannot perform operation: another operation is in progress

The above exception was the direct cause of the following exception:
E   sqlalchemy.dialects.postgresql.asyncpg.AsyncAdapt_asyncpg_dbapi.InterfaceError: <class 'asyncpg.exceptions._base.InterfaceError'>: cannot perform operation: another operation is in progress

The above exception was the direct cause of the following exception:
E   sqlalchemy.exc.InterfaceError: (sqlalchemy.dialects.postgresql.asyncpg.InterfaceError) <class 'asyncpg.exceptions._base.InterfaceError'>: cannot perform operation: another operation is in progress
    [SQL: SELECT users.id, users.email, users.hashed_password, users.username, users.full_name, users.is_active, users.is_superuser, users.is_verified, users.password_reset_token, users.password_reset_at, users.email_verification_token, users.email_verified_at, users.last_login_at, users.login_count, users.created_at, users.updated_at 
    FROM users 
    WHERE users.is_superuser = true]
    (Background on this error at: https://sqlalche.me/e/20/rvf5)
---------------------------- Captured stdout setup -----------------------------
ðŸš€ Starting StackWizard Backend...
2025-08-19 14:48:22,815 INFO sqlalchemy.engine.Engine BEGIN (implicit)
2025-08-19 14:48:22,815 INFO sqlalchemy.engine.Engine SELECT users.id, users.email, users.hashed_password, users.username, users.full_name, users.is_active, users.is_superuser, users.is_verified, users.password_reset_token, users.password_reset_at, users.email_verification_token, users.email_verified_at, users.last_login_at, users.login_count, users.created_at, users.updated_at 
FROM users 
WHERE users.is_superuser = true
2025-08-19 14:48:22,815 INFO sqlalchemy.engine.Engine [cached since 1.281s ago] ()
2025-08-19 14:48:22,815 INFO sqlalchemy.engine.Engine ROLLBACK
------------------------------ Captured log setup ------------------------------
INFO     sqlalchemy.engine.Engine:base.py:2689 BEGIN (implicit)
INFO     sqlalchemy.engine.Engine:base.py:1848 SELECT users.id, users.email, users.hashed_password, users.username, users.full_name, users.is_active, users.is_superuser, users.is_verified, users.password_reset_token, users.password_reset_at, users.email_verification_token, users.email_verified_at, users.last_login_at, users.login_count, users.created_at, users.updated_at 
FROM users 
WHERE users.is_superuser = true
INFO     sqlalchemy.engine.Engine:base.py:1848 [cached since 1.281s ago] ()
INFO     sqlalchemy.engine.Engine:base.py:2692 ROLLBACK
_______ ERROR at setup of TestAuthEndpoints.test_login_endpoint_success ________
E   asyncpg.exceptions._base.InterfaceError: cannot perform operation: another operation is in progress

The above exception was the direct cause of the following exception:
E   sqlalchemy.dialects.postgresql.asyncpg.AsyncAdapt_asyncpg_dbapi.InterfaceError: <class 'asyncpg.exceptions._base.InterfaceError'>: cannot perform operation: another operation is in progress

The above exception was the direct cause of the following exception:
E   sqlalchemy.exc.InterfaceError: (sqlalchemy.dialects.postgresql.asyncpg.InterfaceError) <class 'asyncpg.exceptions._base.InterfaceError'>: cannot perform operation: another operation is in progress
    [SQL: SELECT users.id, users.email, users.hashed_password, users.username, users.full_name, users.is_active, users.is_superuser, users.is_verified, users.password_reset_token, users.password_reset_at, users.email_verification_token, users.email_verified_at, users.last_login_at, users.login_count, users.created_at, users.updated_at 
    FROM users 
    WHERE users.is_superuser = true]
    (Background on this error at: https://sqlalche.me/e/20/rvf5)
---------------------------- Captured stdout setup -----------------------------
ðŸš€ Starting StackWizard Backend...
2025-08-19 14:48:24,403 INFO sqlalchemy.engine.Engine BEGIN (implicit)
2025-08-19 14:48:24,403 INFO sqlalchemy.engine.Engine SELECT users.id, users.email, users.hashed_password, users.username, users.full_name, users.is_active, users.is_superuser, users.is_verified, users.password_reset_token, users.password_reset_at, users.email_verification_token, users.email_verified_at, users.last_login_at, users.login_count, users.created_at, users.updated_at 
FROM users 
WHERE users.is_superuser = true
2025-08-19 14:48:24,403 INFO sqlalchemy.engine.Engine [cached since 2.869s ago] ()
2025-08-19 14:48:24,403 INFO sqlalchemy.engine.Engine ROLLBACK
------------------------------ Captured log setup ------------------------------
INFO     sqlalchemy.engine.Engine:base.py:2689 BEGIN (implicit)
INFO     sqlalchemy.engine.Engine:base.py:1848 SELECT users.id, users.email, users.hashed_password, users.username, users.full_name, users.is_active, users.is_superuser, users.is_verified, users.password_reset_token, users.password_reset_at, users.email_verification_token, users.email_verified_at, users.last_login_at, users.login_count, users.created_at, users.updated_at 
FROM users 
WHERE users.is_superuser = true
INFO     sqlalchemy.engine.Engine:base.py:1848 [cached since 2.869s ago] ()
INFO     sqlalchemy.engine.Engine:base.py:2692 ROLLBACK
___ ERROR at setup of TestAuthEndpoints.test_login_endpoint_invalid_password ___
E   asyncpg.exceptions._base.InterfaceError: cannot perform operation: another operation is in progress

The above exception was the direct cause of the following exception:
E   sqlalchemy.dialects.postgresql.asyncpg.AsyncAdapt_asyncpg_dbapi.InterfaceError: <class 'asyncpg.exceptions._base.InterfaceError'>: cannot perform operation: another operation is in progress

The above exception was the direct cause of the following exception:
E   sqlalchemy.exc.InterfaceError: (sqlalchemy.dialects.postgresql.asyncpg.InterfaceError) <class 'asyncpg.exceptions._base.InterfaceError'>: cannot perform operation: another operation is in progress
    [SQL: SELECT users.id, users.email, users.hashed_password, users.username, users.full_name, users.is_active, users.is_superuser, users.is_verified, users.password_reset_token, users.password_reset_at, users.email_verification_token, users.email_verified_at, users.last_login_at, users.login_count, users.created_at, users.updated_at 
    FROM users 
    WHERE users.is_superuser = true]
    (Background on this error at: https://sqlalche.me/e/20/rvf5)
---------------------------- Captured stdout setup -----------------------------
ðŸš€ Starting StackWizard Backend...
2025-08-19 14:48:24,431 INFO sqlalchemy.engine.Engine BEGIN (implicit)
2025-08-19 14:48:24,431 INFO sqlalchemy.engine.Engine SELECT users.id, users.email, users.hashed_password, users.username, users.full_name, users.is_active, users.is_superuser, users.is_verified, users.password_reset_token, users.password_reset_at, users.email_verification_token, users.email_verified_at, users.last_login_at, users.login_count, users.created_at, users.updated_at 
FROM users 
WHERE users.is_superuser = true
2025-08-19 14:48:24,431 INFO sqlalchemy.engine.Engine [cached since 2.897s ago] ()
2025-08-19 14:48:24,432 INFO sqlalchemy.engine.Engine ROLLBACK
------------------------------ Captured log setup ------------------------------
INFO     sqlalchemy.engine.Engine:base.py:2689 BEGIN (implicit)
INFO     sqlalchemy.engine.Engine:base.py:1848 SELECT users.id, users.email, users.hashed_password, users.username, users.full_name, users.is_active, users.is_superuser, users.is_verified, users.password_reset_token, users.password_reset_at, users.email_verification_token, users.email_verified_at, users.last_login_at, users.login_count, users.created_at, users.updated_at 
FROM users 
WHERE users.is_superuser = true
INFO     sqlalchemy.engine.Engine:base.py:1848 [cached since 2.897s ago] ()
INFO     sqlalchemy.engine.Engine:base.py:2692 ROLLBACK
___ ERROR at setup of TestAuthEndpoints.test_login_endpoint_nonexistent_user ___
E   asyncpg.exceptions._base.InterfaceError: cannot perform operation: another operation is in progress

The above exception was the direct cause of the following exception:
E   sqlalchemy.dialects.postgresql.asyncpg.AsyncAdapt_asyncpg_dbapi.InterfaceError: <class 'asyncpg.exceptions._base.InterfaceError'>: cannot perform operation: another operation is in progress

The above exception was the direct cause of the following exception:
E   sqlalchemy.exc.InterfaceError: (sqlalchemy.dialects.postgresql.asyncpg.InterfaceError) <class 'asyncpg.exceptions._base.InterfaceError'>: cannot perform operation: another operation is in progress
    [SQL: SELECT users.id, users.email, users.hashed_password, users.username, users.full_name, users.is_active, users.is_superuser, users.is_verified, users.password_reset_token, users.password_reset_at, users.email_verification_token, users.email_verified_at, users.last_login_at, users.login_count, users.created_at, users.updated_at 
    FROM users 
    WHERE users.is_superuser = true]
    (Background on this error at: https://sqlalche.me/e/20/rvf5)
---------------------------- Captured stdout setup -----------------------------
ðŸš€ Starting StackWizard Backend...
2025-08-19 14:48:24,458 INFO sqlalchemy.engine.Engine BEGIN (implicit)
2025-08-19 14:48:24,459 INFO sqlalchemy.engine.Engine SELECT users.id, users.email, users.hashed_password, users.username, users.full_name, users.is_active, users.is_superuser, users.is_verified, users.password_reset_token, users.password_reset_at, users.email_verification_token, users.email_verified_at, users.last_login_at, users.login_count, users.created_at, users.updated_at 
FROM users 
WHERE users.is_superuser = true
2025-08-19 14:48:24,459 INFO sqlalchemy.engine.Engine [cached since 2.924s ago] ()
2025-08-19 14:48:24,459 INFO sqlalchemy.engine.Engine ROLLBACK
------------------------------ Captured log setup ------------------------------
INFO     sqlalchemy.engine.Engine:base.py:2689 BEGIN (implicit)
INFO     sqlalchemy.engine.Engine:base.py:1848 SELECT users.id, users.email, users.hashed_password, users.username, users.full_name, users.is_active, users.is_superuser, users.is_verified, users.password_reset_token, users.password_reset_at, users.email_verification_token, users.email_verified_at, users.last_login_at, users.login_count, users.created_at, users.updated_at 
FROM users 
WHERE users.is_superuser = true
INFO     sqlalchemy.engine.Engine:base.py:1848 [cached since 2.924s ago] ()
INFO     sqlalchemy.engine.Engine:base.py:2692 ROLLBACK
______ ERROR at setup of TestAuthEndpoints.test_register_endpoint_success ______
E   asyncpg.exceptions._base.InterfaceError: cannot perform operation: another operation is in progress

The above exception was the direct cause of the following exception:
E   sqlalchemy.dialects.postgresql.asyncpg.AsyncAdapt_asyncpg_dbapi.InterfaceError: <class 'asyncpg.exceptions._base.InterfaceError'>: cannot perform operation: another operation is in progress

The above exception was the direct cause of the following exception:
E   sqlalchemy.exc.InterfaceError: (sqlalchemy.dialects.postgresql.asyncpg.InterfaceError) <class 'asyncpg.exceptions._base.InterfaceError'>: cannot perform operation: another operation is in progress
    [SQL: SELECT users.id, users.email, users.hashed_password, users.username, users.full_name, users.is_active, users.is_superuser, users.is_verified, users.password_reset_token, users.password_reset_at, users.email_verification_token, users.email_verified_at, users.last_login_at, users.login_count, users.created_at, users.updated_at 
    FROM users 
    WHERE users.is_superuser = true]
    (Background on this error at: https://sqlalche.me/e/20/rvf5)
---------------------------- Captured stdout setup -----------------------------
ðŸš€ Starting StackWizard Backend...
2025-08-19 14:48:24,486 INFO sqlalchemy.engine.Engine BEGIN (implicit)
2025-08-19 14:48:24,486 INFO sqlalchemy.engine.Engine SELECT users.id, users.email, users.hashed_password, users.username, users.full_name, users.is_active, users.is_superuser, users.is_verified, users.password_reset_token, users.password_reset_at, users.email_verification_token, users.email_verified_at, users.last_login_at, users.login_count, users.created_at, users.updated_at 
FROM users 
WHERE users.is_superuser = true
2025-08-19 14:48:24,486 INFO sqlalchemy.engine.Engine [cached since 2.952s ago] ()
2025-08-19 14:48:24,486 INFO sqlalchemy.engine.Engine ROLLBACK
------------------------------ Captured log setup ------------------------------
INFO     sqlalchemy.engine.Engine:base.py:2689 BEGIN (implicit)
INFO     sqlalchemy.engine.Engine:base.py:1848 SELECT users.id, users.email, users.hashed_password, users.username, users.full_name, users.is_active, users.is_superuser, users.is_verified, users.password_reset_token, users.password_reset_at, users.email_verification_token, users.email_verified_at, users.last_login_at, users.login_count, users.created_at, users.updated_at 
FROM users 
WHERE users.is_superuser = true
INFO     sqlalchemy.engine.Engine:base.py:1848 [cached since 2.952s ago] ()
INFO     sqlalchemy.engine.Engine:base.py:2692 ROLLBACK
__ ERROR at setup of TestAuthEndpoints.test_register_endpoint_duplicate_email __
E   asyncpg.exceptions._base.InterfaceError: cannot perform operation: another operation is in progress

The above exception was the direct cause of the following exception:
E   sqlalchemy.dialects.postgresql.asyncpg.AsyncAdapt_asyncpg_dbapi.InterfaceError: <class 'asyncpg.exceptions._base.InterfaceError'>: cannot perform operation: another operation is in progress

The above exception was the direct cause of the following exception:
E   sqlalchemy.exc.InterfaceError: (sqlalchemy.dialects.postgresql.asyncpg.InterfaceError) <class 'asyncpg.exceptions._base.InterfaceError'>: cannot perform operation: another operation is in progress
    [SQL: SELECT users.id, users.email, users.hashed_password, users.username, users.full_name, users.is_active, users.is_superuser, users.is_verified, users.password_reset_token, users.password_reset_at, users.email_verification_token, users.email_verified_at, users.last_login_at, users.login_count, users.created_at, users.updated_at 
    FROM users 
    WHERE users.is_superuser = true]
    (Background on this error at: https://sqlalche.me/e/20/rvf5)
---------------------------- Captured stdout setup -----------------------------
ðŸš€ Starting StackWizard Backend...
2025-08-19 14:48:24,514 INFO sqlalchemy.engine.Engine BEGIN (implicit)
2025-08-19 14:48:24,514 INFO sqlalchemy.engine.Engine SELECT users.id, users.email, users.hashed_password, users.username, users.full_name, users.is_active, users.is_superuser, users.is_verified, users.password_reset_token, users.password_reset_at, users.email_verification_token, users.email_verified_at, users.last_login_at, users.login_count, users.created_at, users.updated_at 
FROM users 
WHERE users.is_superuser = true
2025-08-19 14:48:24,514 INFO sqlalchemy.engine.Engine [cached since 2.98s ago] ()
2025-08-19 14:48:24,514 INFO sqlalchemy.engine.Engine ROLLBACK
------------------------------ Captured log setup ------------------------------
INFO     sqlalchemy.engine.Engine:base.py:2689 BEGIN (implicit)
INFO     sqlalchemy.engine.Engine:base.py:1848 SELECT users.id, users.email, users.hashed_password, users.username, users.full_name, users.is_active, users.is_superuser, users.is_verified, users.password_reset_token, users.password_reset_at, users.email_verification_token, users.email_verified_at, users.last_login_at, users.login_count, users.created_at, users.updated_at 
FROM users 
WHERE users.is_superuser = true
INFO     sqlalchemy.engine.Engine:base.py:1848 [cached since 2.98s ago] ()
INFO     sqlalchemy.engine.Engine:base.py:2692 ROLLBACK
___ ERROR at setup of TestAuthEndpoints.test_register_endpoint_weak_password ___
E   asyncpg.exceptions._base.InterfaceError: cannot perform operation: another operation is in progress

The above exception was the direct cause of the following exception:
E   sqlalchemy.dialects.postgresql.asyncpg.AsyncAdapt_asyncpg_dbapi.InterfaceError: <class 'asyncpg.exceptions._base.InterfaceError'>: cannot perform operation: another operation is in progress

The above exception was the direct cause of the following exception:
E   sqlalchemy.exc.InterfaceError: (sqlalchemy.dialects.postgresql.asyncpg.InterfaceError) <class 'asyncpg.exceptions._base.InterfaceError'>: cannot perform operation: another operation is in progress
    [SQL: SELECT users.id, users.email, users.hashed_password, users.username, users.full_name, users.is_active, users.is_superuser, users.is_verified, users.password_reset_token, users.password_reset_at, users.email_verification_token, users.email_verified_at, users.last_login_at, users.login_count, users.created_at, users.updated_at 
    FROM users 
    WHERE users.is_superuser = true]
    (Background on this error at: https://sqlalche.me/e/20/rvf5)
---------------------------- Captured stdout setup -----------------------------
ðŸš€ Starting StackWizard Backend...
2025-08-19 14:48:24,540 INFO sqlalchemy.engine.Engine BEGIN (implicit)
2025-08-19 14:48:24,540 INFO sqlalchemy.engine.Engine SELECT users.id, users.email, users.hashed_password, users.username, users.full_name, users.is_active, users.is_superuser, users.is_verified, users.password_reset_token, users.password_reset_at, users.email_verification_token, users.email_verified_at, users.last_login_at, users.login_count, users.created_at, users.updated_at 
FROM users 
WHERE users.is_superuser = true
2025-08-19 14:48:24,540 INFO sqlalchemy.engine.Engine [cached since 3.006s ago] ()
2025-08-19 14:48:24,541 INFO sqlalchemy.engine.Engine ROLLBACK
------------------------------ Captured log setup ------------------------------
INFO     sqlalchemy.engine.Engine:base.py:2689 BEGIN (implicit)
INFO     sqlalchemy.engine.Engine:base.py:1848 SELECT users.id, users.email, users.hashed_password, users.username, users.full_name, users.is_active, users.is_superuser, users.is_verified, users.password_reset_token, users.password_reset_at, users.email_verification_token, users.email_verified_at, users.last_login_at, users.login_count, users.created_at, users.updated_at 
FROM users 
WHERE users.is_superuser = true
INFO     sqlalchemy.engine.Engine:base.py:1848 [cached since 3.006s ago] ()
INFO     sqlalchemy.engine.Engine:base.py:2692 ROLLBACK
_______ ERROR at setup of TestAuthEndpoints.test_refresh_token_endpoint ________
E   asyncpg.exceptions._base.InterfaceError: cannot perform operation: another operation is in progress

The above exception was the direct cause of the following exception:
E   sqlalchemy.dialects.postgresql.asyncpg.AsyncAdapt_asyncpg_dbapi.InterfaceError: <class 'asyncpg.exceptions._base.InterfaceError'>: cannot perform operation: another operation is in progress

The above exception was the direct cause of the following exception:
E   sqlalchemy.exc.InterfaceError: (sqlalchemy.dialects.postgresql.asyncpg.InterfaceError) <class 'asyncpg.exceptions._base.InterfaceError'>: cannot perform operation: another operation is in progress
    [SQL: SELECT users.id, users.email, users.hashed_password, users.username, users.full_name, users.is_active, users.is_superuser, users.is_verified, users.password_reset_token, users.password_reset_at, users.email_verification_token, users.email_verified_at, users.last_login_at, users.login_count, users.created_at, users.updated_at 
    FROM users 
    WHERE users.is_superuser = true]
    (Background on this error at: https://sqlalche.me/e/20/rvf5)
---------------------------- Captured stdout setup -----------------------------
ðŸš€ Starting StackWizard Backend...
2025-08-19 14:48:24,600 INFO sqlalchemy.engine.Engine BEGIN (implicit)
2025-08-19 14:48:24,600 INFO sqlalchemy.engine.Engine SELECT users.id, users.email, users.hashed_password, users.username, users.full_name, users.is_active, users.is_superuser, users.is_verified, users.password_reset_token, users.password_reset_at, users.email_verification_token, users.email_verified_at, users.last_login_at, users.login_count, users.created_at, users.updated_at 
FROM users 
WHERE users.is_superuser = true
2025-08-19 14:48:24,600 INFO sqlalchemy.engine.Engine [cached since 3.065s ago] ()
2025-08-19 14:48:24,600 INFO sqlalchemy.engine.Engine ROLLBACK
------------------------------ Captured log setup ------------------------------
INFO     sqlalchemy.engine.Engine:base.py:2689 BEGIN (implicit)
INFO     sqlalchemy.engine.Engine:base.py:1848 SELECT users.id, users.email, users.hashed_password, users.username, users.full_name, users.is_active, users.is_superuser, users.is_verified, users.password_reset_token, users.password_reset_at, users.email_verification_token, users.email_verified_at, users.last_login_at, users.login_count, users.created_at, users.updated_at 
FROM users 
WHERE users.is_superuser = true
INFO     sqlalchemy.engine.Engine:base.py:1848 [cached since 3.065s ago] ()
INFO     sqlalchemy.engine.Engine:base.py:2692 ROLLBACK
________ ERROR at setup of TestAuthEndpoints.test_refresh_token_invalid ________
E   asyncpg.exceptions._base.InterfaceError: cannot perform operation: another operation is in progress

The above exception was the direct cause of the following exception:
E   sqlalchemy.dialects.postgresql.asyncpg.AsyncAdapt_asyncpg_dbapi.InterfaceError: <class 'asyncpg.exceptions._base.InterfaceError'>: cannot perform operation: another operation is in progress

The above exception was the direct cause of the following exception:
E   sqlalchemy.exc.InterfaceError: (sqlalchemy.dialects.postgresql.asyncpg.InterfaceError) <class 'asyncpg.exceptions._base.InterfaceError'>: cannot perform operation: another operation is in progress
    [SQL: SELECT users.id, users.email, users.hashed_password, users.username, users.full_name, users.is_active, users.is_superuser, users.is_verified, users.password_reset_token, users.password_reset_at, users.email_verification_token, users.email_verified_at, users.last_login_at, users.login_count, users.created_at, users.updated_at 
    FROM users 
    WHERE users.is_superuser = true]
    (Background on this error at: https://sqlalche.me/e/20/rvf5)
---------------------------- Captured stdout setup -----------------------------
ðŸš€ Starting StackWizard Backend...
2025-08-19 14:48:24,627 INFO sqlalchemy.engine.Engine BEGIN (implicit)
2025-08-19 14:48:24,628 INFO sqlalchemy.engine.Engine SELECT users.id, users.email, users.hashed_password, users.username, users.full_name, users.is_active, users.is_superuser, users.is_verified, users.password_reset_token, users.password_reset_at, users.email_verification_token, users.email_verified_at, users.last_login_at, users.login_count, users.created_at, users.updated_at 
FROM users 
WHERE users.is_superuser = true
2025-08-19 14:48:24,628 INFO sqlalchemy.engine.Engine [cached since 3.093s ago] ()
2025-08-19 14:48:24,628 INFO sqlalchemy.engine.Engine ROLLBACK
------------------------------ Captured log setup ------------------------------
INFO     sqlalchemy.engine.Engine:base.py:2689 BEGIN (implicit)
INFO     sqlalchemy.engine.Engine:base.py:1848 SELECT users.id, users.email, users.hashed_password, users.username, users.full_name, users.is_active, users.is_superuser, users.is_verified, users.password_reset_token, users.password_reset_at, users.email_verification_token, users.email_verified_at, users.last_login_at, users.login_count, users.created_at, users.updated_at 
FROM users 
WHERE users.is_superuser = true
INFO     sqlalchemy.engine.Engine:base.py:1848 [cached since 3.093s ago] ()
INFO     sqlalchemy.engine.Engine:base.py:2692 ROLLBACK
__________ ERROR at setup of TestUserEndpoints.test_get_current_user ___________
E   asyncpg.exceptions._base.InterfaceError: cannot perform operation: another operation is in progress

The above exception was the direct cause of the following exception:
E   sqlalchemy.dialects.postgresql.asyncpg.AsyncAdapt_asyncpg_dbapi.InterfaceError: <class 'asyncpg.exceptions._base.InterfaceError'>: cannot perform operation: another operation is in progress

The above exception was the direct cause of the following exception:
E   sqlalchemy.exc.InterfaceError: (sqlalchemy.dialects.postgresql.asyncpg.InterfaceError) <class 'asyncpg.exceptions._base.InterfaceError'>: cannot perform operation: another operation is in progress
    [SQL: SELECT users.id, users.email, users.hashed_password, users.username, users.full_name, users.is_active, users.is_superuser, users.is_verified, users.password_reset_token, users.password_reset_at, users.email_verification_token, users.email_verified_at, users.last_login_at, users.login_count, users.created_at, users.updated_at 
    FROM users 
    WHERE users.is_superuser = true]
    (Background on this error at: https://sqlalche.me/e/20/rvf5)
---------------------------- Captured stdout setup -----------------------------
ðŸš€ Starting StackWizard Backend...
2025-08-19 14:48:25,749 INFO sqlalchemy.engine.Engine BEGIN (implicit)
2025-08-19 14:48:25,749 INFO sqlalchemy.engine.Engine SELECT users.id, users.email, users.hashed_password, users.username, users.full_name, users.is_active, users.is_superuser, users.is_verified, users.password_reset_token, users.password_reset_at, users.email_verification_token, users.email_verified_at, users.last_login_at, users.login_count, users.created_at, users.updated_at 
FROM users 
WHERE users.is_superuser = true
2025-08-19 14:48:25,749 INFO sqlalchemy.engine.Engine [cached since 4.215s ago] ()
2025-08-19 14:48:25,750 INFO sqlalchemy.engine.Engine ROLLBACK
------------------------------ Captured log setup ------------------------------
INFO     sqlalchemy.engine.Engine:base.py:2689 BEGIN (implicit)
INFO     sqlalchemy.engine.Engine:base.py:1848 SELECT users.id, users.email, users.hashed_password, users.username, users.full_name, users.is_active, users.is_superuser, users.is_verified, users.password_reset_token, users.password_reset_at, users.email_verification_token, users.email_verified_at, users.last_login_at, users.login_count, users.created_at, users.updated_at 
FROM users 
WHERE users.is_superuser = true
INFO     sqlalchemy.engine.Engine:base.py:1848 [cached since 4.215s ago] ()
INFO     sqlalchemy.engine.Engine:base.py:2692 ROLLBACK
____ ERROR at setup of TestUserEndpoints.test_get_current_user_unauthorized ____
E   asyncpg.exceptions._base.InterfaceError: cannot perform operation: another operation is in progress

The above exception was the direct cause of the following exception:
E   sqlalchemy.dialects.postgresql.asyncpg.AsyncAdapt_asyncpg_dbapi.InterfaceError: <class 'asyncpg.exceptions._base.InterfaceError'>: cannot perform operation: another operation is in progress

The above exception was the direct cause of the following exception:
E   sqlalchemy.exc.InterfaceError: (sqlalchemy.dialects.postgresql.asyncpg.InterfaceError) <class 'asyncpg.exceptions._base.InterfaceError'>: cannot perform operation: another operation is in progress
    [SQL: SELECT users.id, users.email, users.hashed_password, users.username, users.full_name, users.is_active, users.is_superuser, users.is_verified, users.password_reset_token, users.password_reset_at, users.email_verification_token, users.email_verified_at, users.last_login_at, users.login_count, users.created_at, users.updated_at 
    FROM users 
    WHERE users.is_superuser = true]
    (Background on this error at: https://sqlalche.me/e/20/rvf5)
---------------------------- Captured stdout setup -----------------------------
ðŸš€ Starting StackWizard Backend...
2025-08-19 14:48:25,787 INFO sqlalchemy.engine.Engine BEGIN (implicit)
2025-08-19 14:48:25,787 INFO sqlalchemy.engine.Engine SELECT users.id, users.email, users.hashed_password, users.username, users.full_name, users.is_active, users.is_superuser, users.is_verified, users.password_reset_token, users.password_reset_at, users.email_verification_token, users.email_verified_at, users.last_login_at, users.login_count, users.created_at, users.updated_at 
FROM users 
WHERE users.is_superuser = true
2025-08-19 14:48:25,787 INFO sqlalchemy.engine.Engine [cached since 4.253s ago] ()
2025-08-19 14:48:25,787 INFO sqlalchemy.engine.Engine ROLLBACK
------------------------------ Captured log setup ------------------------------
INFO     sqlalchemy.engine.Engine:base.py:2689 BEGIN (implicit)
INFO     sqlalchemy.engine.Engine:base.py:1848 SELECT users.id, users.email, users.hashed_password, users.username, users.full_name, users.is_active, users.is_superuser, users.is_verified, users.password_reset_token, users.password_reset_at, users.email_verification_token, users.email_verified_at, users.last_login_at, users.login_count, users.created_at, users.updated_at 
FROM users 
WHERE users.is_superuser = true
INFO     sqlalchemy.engine.Engine:base.py:1848 [cached since 4.253s ago] ()
INFO     sqlalchemy.engine.Engine:base.py:2692 ROLLBACK
___ ERROR at setup of TestUserEndpoints.test_get_current_user_invalid_token ____
E   asyncpg.exceptions._base.InterfaceError: cannot perform operation: another operation is in progress

The above exception was the direct cause of the following exception:
E   sqlalchemy.dialects.postgresql.asyncpg.AsyncAdapt_asyncpg_dbapi.InterfaceError: <class 'asyncpg.exceptions._base.InterfaceError'>: cannot perform operation: another operation is in progress

The above exception was the direct cause of the following exception:
E   sqlalchemy.exc.InterfaceError: (sqlalchemy.dialects.postgresql.asyncpg.InterfaceError) <class 'asyncpg.exceptions._base.InterfaceError'>: cannot perform operation: another operation is in progress
    [SQL: SELECT users.id, users.email, users.hashed_password, users.username, users.full_name, users.is_active, users.is_superuser, users.is_verified, users.password_reset_token, users.password_reset_at, users.email_verification_token, users.email_verified_at, users.last_login_at, users.login_count, users.created_at, users.updated_at 
    FROM users 
    WHERE users.is_superuser = true]
    (Background on this error at: https://sqlalche.me/e/20/rvf5)
---------------------------- Captured stdout setup -----------------------------
ðŸš€ Starting StackWizard Backend...
2025-08-19 14:48:25,815 INFO sqlalchemy.engine.Engine BEGIN (implicit)
2025-08-19 14:48:25,815 INFO sqlalchemy.engine.Engine SELECT users.id, users.email, users.hashed_password, users.username, users.full_name, users.is_active, users.is_superuser, users.is_verified, users.password_reset_token, users.password_reset_at, users.email_verification_token, users.email_verified_at, users.last_login_at, users.login_count, users.created_at, users.updated_at 
FROM users 
WHERE users.is_superuser = true
2025-08-19 14:48:25,815 INFO sqlalchemy.engine.Engine [cached since 4.281s ago] ()
2025-08-19 14:48:25,815 INFO sqlalchemy.engine.Engine ROLLBACK
------------------------------ Captured log setup ------------------------------
INFO     sqlalchemy.engine.Engine:base.py:2689 BEGIN (implicit)
INFO     sqlalchemy.engine.Engine:base.py:1848 SELECT users.id, users.email, users.hashed_password, users.username, users.full_name, users.is_active, users.is_superuser, users.is_verified, users.password_reset_token, users.password_reset_at, users.email_verification_token, users.email_verified_at, users.last_login_at, users.login_count, users.created_at, users.updated_at 
FROM users 
WHERE users.is_superuser = true
INFO     sqlalchemy.engine.Engine:base.py:1848 [cached since 4.281s ago] ()
INFO     sqlalchemy.engine.Engine:base.py:2692 ROLLBACK
_________ ERROR at setup of TestUserEndpoints.test_update_current_user _________
E   asyncpg.exceptions._base.InterfaceError: cannot perform operation: another operation is in progress

The above exception was the direct cause of the following exception:
E   sqlalchemy.dialects.postgresql.asyncpg.AsyncAdapt_asyncpg_dbapi.InterfaceError: <class 'asyncpg.exceptions._base.InterfaceError'>: cannot perform operation: another operation is in progress

The above exception was the direct cause of the following exception:
E   sqlalchemy.exc.InterfaceError: (sqlalchemy.dialects.postgresql.asyncpg.InterfaceError) <class 'asyncpg.exceptions._base.InterfaceError'>: cannot perform operation: another operation is in progress
    [SQL: SELECT users.id, users.email, users.hashed_password, users.username, users.full_name, users.is_active, users.is_superuser, users.is_verified, users.password_reset_token, users.password_reset_at, users.email_verification_token, users.email_verified_at, users.last_login_at, users.login_count, users.created_at, users.updated_at 
    FROM users 
    WHERE users.is_superuser = true]
    (Background on this error at: https://sqlalche.me/e/20/rvf5)
---------------------------- Captured stdout setup -----------------------------
ðŸš€ Starting StackWizard Backend...
2025-08-19 14:48:25,843 INFO sqlalchemy.engine.Engine BEGIN (implicit)
2025-08-19 14:48:25,843 INFO sqlalchemy.engine.Engine SELECT users.id, users.email, users.hashed_password, users.username, users.full_name, users.is_active, users.is_superuser, users.is_verified, users.password_reset_token, users.password_reset_at, users.email_verification_token, users.email_verified_at, users.last_login_at, users.login_count, users.created_at, users.updated_at 
FROM users 
WHERE users.is_superuser = true
2025-08-19 14:48:25,843 INFO sqlalchemy.engine.Engine [cached since 4.308s ago] ()
2025-08-19 14:48:25,843 INFO sqlalchemy.engine.Engine ROLLBACK
------------------------------ Captured log setup ------------------------------
INFO     sqlalchemy.engine.Engine:base.py:2689 BEGIN (implicit)
INFO     sqlalchemy.engine.Engine:base.py:1848 SELECT users.id, users.email, users.hashed_password, users.username, users.full_name, users.is_active, users.is_superuser, users.is_verified, users.password_reset_token, users.password_reset_at, users.email_verification_token, users.email_verified_at, users.last_login_at, users.login_count, users.created_at, users.updated_at 
FROM users 
WHERE users.is_superuser = true
INFO     sqlalchemy.engine.Engine:base.py:1848 [cached since 4.308s ago] ()
INFO     sqlalchemy.engine.Engine:base.py:2692 ROLLBACK
_ ERROR at setup of TestUserEndpoints.test_update_current_user_duplicate_email _
E   asyncpg.exceptions._base.InterfaceError: cannot perform operation: another operation is in progress

The above exception was the direct cause of the following exception:
E   sqlalchemy.dialects.postgresql.asyncpg.AsyncAdapt_asyncpg_dbapi.InterfaceError: <class 'asyncpg.exceptions._base.InterfaceError'>: cannot perform operation: another operation is in progress

The above exception was the direct cause of the following exception:
E   sqlalchemy.exc.InterfaceError: (sqlalchemy.dialects.postgresql.asyncpg.InterfaceError) <class 'asyncpg.exceptions._base.InterfaceError'>: cannot perform operation: another operation is in progress
    [SQL: SELECT users.id, users.email, users.hashed_password, users.username, users.full_name, users.is_active, users.is_superuser, users.is_verified, users.password_reset_token, users.password_reset_at, users.email_verification_token, users.email_verified_at, users.last_login_at, users.login_count, users.created_at, users.updated_at 
    FROM users 
    WHERE users.is_superuser = true]
    (Background on this error at: https://sqlalche.me/e/20/rvf5)
---------------------------- Captured stdout setup -----------------------------
ðŸš€ Starting StackWizard Backend...
2025-08-19 14:48:25,871 INFO sqlalchemy.engine.Engine BEGIN (implicit)
2025-08-19 14:48:25,871 INFO sqlalchemy.engine.Engine SELECT users.id, users.email, users.hashed_password, users.username, users.full_name, users.is_active, users.is_superuser, users.is_verified, users.password_reset_token, users.password_reset_at, users.email_verification_token, users.email_verified_at, users.last_login_at, users.login_count, users.created_at, users.updated_at 
FROM users 
WHERE users.is_superuser = true
2025-08-19 14:48:25,871 INFO sqlalchemy.engine.Engine [cached since 4.336s ago] ()
2025-08-19 14:48:25,871 INFO sqlalchemy.engine.Engine ROLLBACK
------------------------------ Captured log setup ------------------------------
INFO     sqlalchemy.engine.Engine:base.py:2689 BEGIN (implicit)
INFO     sqlalchemy.engine.Engine:base.py:1848 SELECT users.id, users.email, users.hashed_password, users.username, users.full_name, users.is_active, users.is_superuser, users.is_verified, users.password_reset_token, users.password_reset_at, users.email_verification_token, users.email_verified_at, users.last_login_at, users.login_count, users.created_at, users.updated_at 
FROM users 
WHERE users.is_superuser = true
INFO     sqlalchemy.engine.Engine:base.py:1848 [cached since 4.336s ago] ()
INFO     sqlalchemy.engine.Engine:base.py:2692 ROLLBACK
________ ERROR at setup of TestUserEndpoints.test_update_user_password _________
E   asyncpg.exceptions._base.InterfaceError: cannot perform operation: another operation is in progress

The above exception was the direct cause of the following exception:
E   sqlalchemy.dialects.postgresql.asyncpg.AsyncAdapt_asyncpg_dbapi.InterfaceError: <class 'asyncpg.exceptions._base.InterfaceError'>: cannot perform operation: another operation is in progress

The above exception was the direct cause of the following exception:
E   sqlalchemy.exc.InterfaceError: (sqlalchemy.dialects.postgresql.asyncpg.InterfaceError) <class 'asyncpg.exceptions._base.InterfaceError'>: cannot perform operation: another operation is in progress
    [SQL: SELECT users.id, users.email, users.hashed_password, users.username, users.full_name, users.is_active, users.is_superuser, users.is_verified, users.password_reset_token, users.password_reset_at, users.email_verification_token, users.email_verified_at, users.last_login_at, users.login_count, users.created_at, users.updated_at 
    FROM users 
    WHERE users.is_superuser = true]
    (Background on this error at: https://sqlalche.me/e/20/rvf5)
---------------------------- Captured stdout setup -----------------------------
ðŸš€ Starting StackWizard Backend...
2025-08-19 14:48:25,901 INFO sqlalchemy.engine.Engine BEGIN (implicit)
2025-08-19 14:48:25,901 INFO sqlalchemy.engine.Engine SELECT users.id, users.email, users.hashed_password, users.username, users.full_name, users.is_active, users.is_superuser, users.is_verified, users.password_reset_token, users.password_reset_at, users.email_verification_token, users.email_verified_at, users.last_login_at, users.login_count, users.created_at, users.updated_at 
FROM users 
WHERE users.is_superuser = true
2025-08-19 14:48:25,901 INFO sqlalchemy.engine.Engine [cached since 4.367s ago] ()
2025-08-19 14:48:25,901 INFO sqlalchemy.engine.Engine ROLLBACK
------------------------------ Captured log setup ------------------------------
INFO     sqlalchemy.engine.Engine:base.py:2689 BEGIN (implicit)
INFO     sqlalchemy.engine.Engine:base.py:1848 SELECT users.id, users.email, users.hashed_password, users.username, users.full_name, users.is_active, users.is_superuser, users.is_verified, users.password_reset_token, users.password_reset_at, users.email_verification_token, users.email_verified_at, users.last_login_at, users.login_count, users.created_at, users.updated_at 
FROM users 
WHERE users.is_superuser = true
INFO     sqlalchemy.engine.Engine:base.py:1848 [cached since 4.367s ago] ()
INFO     sqlalchemy.engine.Engine:base.py:2692 ROLLBACK
____ ERROR at setup of TestUserEndpoints.test_update_password_wrong_current ____
E   asyncpg.exceptions._base.InterfaceError: cannot perform operation: another operation is in progress

The above exception was the direct cause of the following exception:
E   sqlalchemy.dialects.postgresql.asyncpg.AsyncAdapt_asyncpg_dbapi.InterfaceError: <class 'asyncpg.exceptions._base.InterfaceError'>: cannot perform operation: another operation is in progress

The above exception was the direct cause of the following exception:
E   sqlalchemy.exc.InterfaceError: (sqlalchemy.dialects.postgresql.asyncpg.InterfaceError) <class 'asyncpg.exceptions._base.InterfaceError'>: cannot perform operation: another operation is in progress
    [SQL: SELECT users.id, users.email, users.hashed_password, users.username, users.full_name, users.is_active, users.is_superuser, users.is_verified, users.password_reset_token, users.password_reset_at, users.email_verification_token, users.email_verified_at, users.last_login_at, users.login_count, users.created_at, users.updated_at 
    FROM users 
    WHERE users.is_superuser = true]
    (Background on this error at: https://sqlalche.me/e/20/rvf5)
---------------------------- Captured stdout setup -----------------------------
ðŸš€ Starting StackWizard Backend...
2025-08-19 14:48:25,930 INFO sqlalchemy.engine.Engine BEGIN (implicit)
2025-08-19 14:48:25,930 INFO sqlalchemy.engine.Engine SELECT users.id, users.email, users.hashed_password, users.username, users.full_name, users.is_active, users.is_superuser, users.is_verified, users.password_reset_token, users.password_reset_at, users.email_verification_token, users.email_verified_at, users.last_login_at, users.login_count, users.created_at, users.updated_at 
FROM users 
WHERE users.is_superuser = true
2025-08-19 14:48:25,930 INFO sqlalchemy.engine.Engine [cached since 4.396s ago] ()
2025-08-19 14:48:25,930 INFO sqlalchemy.engine.Engine ROLLBACK
------------------------------ Captured log setup ------------------------------
INFO     sqlalchemy.engine.Engine:base.py:2689 BEGIN (implicit)
INFO     sqlalchemy.engine.Engine:base.py:1848 SELECT users.id, users.email, users.hashed_password, users.username, users.full_name, users.is_active, users.is_superuser, users.is_verified, users.password_reset_token, users.password_reset_at, users.email_verification_token, users.email_verified_at, users.last_login_at, users.login_count, users.created_at, users.updated_at 
FROM users 
WHERE users.is_superuser = true
INFO     sqlalchemy.engine.Engine:base.py:1848 [cached since 4.396s ago] ()
INFO     sqlalchemy.engine.Engine:base.py:2692 ROLLBACK
_________ ERROR at setup of TestUserEndpoints.test_delete_current_user _________
E   asyncpg.exceptions._base.InterfaceError: cannot perform operation: another operation is in progress

The above exception was the direct cause of the following exception:
E   sqlalchemy.dialects.postgresql.asyncpg.AsyncAdapt_asyncpg_dbapi.InterfaceError: <class 'asyncpg.exceptions._base.InterfaceError'>: cannot perform operation: another operation is in progress

The above exception was the direct cause of the following exception:
E   sqlalchemy.exc.InterfaceError: (sqlalchemy.dialects.postgresql.asyncpg.InterfaceError) <class 'asyncpg.exceptions._base.InterfaceError'>: cannot perform operation: another operation is in progress
    [SQL: SELECT users.id, users.email, users.hashed_password, users.username, users.full_name, users.is_active, users.is_superuser, users.is_verified, users.password_reset_token, users.password_reset_at, users.email_verification_token, users.email_verified_at, users.last_login_at, users.login_count, users.created_at, users.updated_at 
    FROM users 
    WHERE users.is_superuser = true]
    (Background on this error at: https://sqlalche.me/e/20/rvf5)
---------------------------- Captured stdout setup -----------------------------
ðŸš€ Starting StackWizard Backend...
2025-08-19 14:48:25,956 INFO sqlalchemy.engine.Engine BEGIN (implicit)
2025-08-19 14:48:25,956 INFO sqlalchemy.engine.Engine SELECT users.id, users.email, users.hashed_password, users.username, users.full_name, users.is_active, users.is_superuser, users.is_verified, users.password_reset_token, users.password_reset_at, users.email_verification_token, users.email_verified_at, users.last_login_at, users.login_count, users.created_at, users.updated_at 
FROM users 
WHERE users.is_superuser = true
2025-08-19 14:48:25,956 INFO sqlalchemy.engine.Engine [cached since 4.422s ago] ()
2025-08-19 14:48:25,957 INFO sqlalchemy.engine.Engine ROLLBACK
------------------------------ Captured log setup ------------------------------
INFO     sqlalchemy.engine.Engine:base.py:2689 BEGIN (implicit)
INFO     sqlalchemy.engine.Engine:base.py:1848 SELECT users.id, users.email, users.hashed_password, users.username, users.full_name, users.is_active, users.is_superuser, users.is_verified, users.password_reset_token, users.password_reset_at, users.email_verification_token, users.email_verified_at, users.last_login_at, users.login_count, users.created_at, users.updated_at 
FROM users 
WHERE users.is_superuser = true
INFO     sqlalchemy.engine.Engine:base.py:1848 [cached since 4.422s ago] ()
INFO     sqlalchemy.engine.Engine:base.py:2692 ROLLBACK
_____ ERROR at setup of TestAdminUserEndpoints.test_get_all_users_as_admin _____
E   asyncpg.exceptions._base.InterfaceError: cannot perform operation: another operation is in progress

The above exception was the direct cause of the following exception:
E   sqlalchemy.dialects.postgresql.asyncpg.AsyncAdapt_asyncpg_dbapi.InterfaceError: <class 'asyncpg.exceptions._base.InterfaceError'>: cannot perform operation: another operation is in progress

The above exception was the direct cause of the following exception:
E   sqlalchemy.exc.InterfaceError: (sqlalchemy.dialects.postgresql.asyncpg.InterfaceError) <class 'asyncpg.exceptions._base.InterfaceError'>: cannot perform operation: another operation is in progress
    [SQL: SELECT users.id, users.email, users.hashed_password, users.username, users.full_name, users.is_active, users.is_superuser, users.is_verified, users.password_reset_token, users.password_reset_at, users.email_verification_token, users.email_verified_at, users.last_login_at, users.login_count, users.created_at, users.updated_at 
    FROM users 
    WHERE users.is_superuser = true]
    (Background on this error at: https://sqlalche.me/e/20/rvf5)
---------------------------- Captured stdout setup -----------------------------
ðŸš€ Starting StackWizard Backend...
2025-08-19 14:48:25,983 INFO sqlalchemy.engine.Engine BEGIN (implicit)
2025-08-19 14:48:25,984 INFO sqlalchemy.engine.Engine SELECT users.id, users.email, users.hashed_password, users.username, users.full_name, users.is_active, users.is_superuser, users.is_verified, users.password_reset_token, users.password_reset_at, users.email_verification_token, users.email_verified_at, users.last_login_at, users.login_count, users.created_at, users.updated_at 
FROM users 
WHERE users.is_superuser = true
2025-08-19 14:48:25,984 INFO sqlalchemy.engine.Engine [cached since 4.449s ago] ()
2025-08-19 14:48:25,984 INFO sqlalchemy.engine.Engine ROLLBACK
------------------------------ Captured log setup ------------------------------
INFO     sqlalchemy.engine.Engine:base.py:2689 BEGIN (implicit)
INFO     sqlalchemy.engine.Engine:base.py:1848 SELECT users.id, users.email, users.hashed_password, users.username, users.full_name, users.is_active, users.is_superuser, users.is_verified, users.password_reset_token, users.password_reset_at, users.email_verification_token, users.email_verified_at, users.last_login_at, users.login_count, users.created_at, users.updated_at 
FROM users 
WHERE users.is_superuser = true
INFO     sqlalchemy.engine.Engine:base.py:1848 [cached since 4.449s ago] ()
INFO     sqlalchemy.engine.Engine:base.py:2692 ROLLBACK
_ ERROR at setup of TestAdminUserEndpoints.test_get_all_users_as_regular_user __
E   asyncpg.exceptions._base.InterfaceError: cannot perform operation: another operation is in progress

The above exception was the direct cause of the following exception:
E   sqlalchemy.dialects.postgresql.asyncpg.AsyncAdapt_asyncpg_dbapi.InterfaceError: <class 'asyncpg.exceptions._base.InterfaceError'>: cannot perform operation: another operation is in progress

The above exception was the direct cause of the following exception:
E   sqlalchemy.exc.InterfaceError: (sqlalchemy.dialects.postgresql.asyncpg.InterfaceError) <class 'asyncpg.exceptions._base.InterfaceError'>: cannot perform operation: another operation is in progress
    [SQL: SELECT users.id, users.email, users.hashed_password, users.username, users.full_name, users.is_active, users.is_superuser, users.is_verified, users.password_reset_token, users.password_reset_at, users.email_verification_token, users.email_verified_at, users.last_login_at, users.login_count, users.created_at, users.updated_at 
    FROM users 
    WHERE users.is_superuser = true]
    (Background on this error at: https://sqlalche.me/e/20/rvf5)
---------------------------- Captured stdout setup -----------------------------
ðŸš€ Starting StackWizard Backend...
2025-08-19 14:48:26,010 INFO sqlalchemy.engine.Engine BEGIN (implicit)
2025-08-19 14:48:26,010 INFO sqlalchemy.engine.Engine SELECT users.id, users.email, users.hashed_password, users.username, users.full_name, users.is_active, users.is_superuser, users.is_verified, users.password_reset_token, users.password_reset_at, users.email_verification_token, users.email_verified_at, users.last_login_at, users.login_count, users.created_at, users.updated_at 
FROM users 
WHERE users.is_superuser = true
2025-08-19 14:48:26,010 INFO sqlalchemy.engine.Engine [cached since 4.476s ago] ()
2025-08-19 14:48:26,010 INFO sqlalchemy.engine.Engine ROLLBACK
------------------------------ Captured log setup ------------------------------
INFO     sqlalchemy.engine.Engine:base.py:2689 BEGIN (implicit)
INFO     sqlalchemy.engine.Engine:base.py:1848 SELECT users.id, users.email, users.hashed_password, users.username, users.full_name, users.is_active, users.is_superuser, users.is_verified, users.password_reset_token, users.password_reset_at, users.email_verification_token, users.email_verified_at, users.last_login_at, users.login_count, users.created_at, users.updated_at 
FROM users 
WHERE users.is_superuser = true
INFO     sqlalchemy.engine.Engine:base.py:1848 [cached since 4.476s ago] ()
INFO     sqlalchemy.engine.Engine:base.py:2692 ROLLBACK
_ ERROR at setup of TestAdminUserEndpoints.test_get_all_users_with_pagination __
E   asyncpg.exceptions._base.InterfaceError: cannot perform operation: another operation is in progress

The above exception was the direct cause of the following exception:
E   sqlalchemy.dialects.postgresql.asyncpg.AsyncAdapt_asyncpg_dbapi.InterfaceError: <class 'asyncpg.exceptions._base.InterfaceError'>: cannot perform operation: another operation is in progress

The above exception was the direct cause of the following exception:
E   sqlalchemy.exc.InterfaceError: (sqlalchemy.dialects.postgresql.asyncpg.InterfaceError) <class 'asyncpg.exceptions._base.InterfaceError'>: cannot perform operation: another operation is in progress
    [SQL: SELECT users.id, users.email, users.hashed_password, users.username, users.full_name, users.is_active, users.is_superuser, users.is_verified, users.password_reset_token, users.password_reset_at, users.email_verification_token, users.email_verified_at, users.last_login_at, users.login_count, users.created_at, users.updated_at 
    FROM users 
    WHERE users.is_superuser = true]
    (Background on this error at: https://sqlalche.me/e/20/rvf5)
---------------------------- Captured stdout setup -----------------------------
ðŸš€ Starting StackWizard Backend...
2025-08-19 14:48:26,037 INFO sqlalchemy.engine.Engine BEGIN (implicit)
2025-08-19 14:48:26,037 INFO sqlalchemy.engine.Engine SELECT users.id, users.email, users.hashed_password, users.username, users.full_name, users.is_active, users.is_superuser, users.is_verified, users.password_reset_token, users.password_reset_at, users.email_verification_token, users.email_verified_at, users.last_login_at, users.login_count, users.created_at, users.updated_at 
FROM users 
WHERE users.is_superuser = true
2025-08-19 14:48:26,038 INFO sqlalchemy.engine.Engine [cached since 4.503s ago] ()
2025-08-19 14:48:26,038 INFO sqlalchemy.engine.Engine ROLLBACK
------------------------------ Captured log setup ------------------------------
INFO     sqlalchemy.engine.Engine:base.py:2689 BEGIN (implicit)
INFO     sqlalchemy.engine.Engine:base.py:1848 SELECT users.id, users.email, users.hashed_password, users.username, users.full_name, users.is_active, users.is_superuser, users.is_verified, users.password_reset_token, users.password_reset_at, users.email_verification_token, users.email_verified_at, users.last_login_at, users.login_count, users.created_at, users.updated_at 
FROM users 
WHERE users.is_superuser = true
INFO     sqlalchemy.engine.Engine:base.py:1848 [cached since 4.503s ago] ()
INFO     sqlalchemy.engine.Engine:base.py:2692 ROLLBACK
____ ERROR at setup of TestAdminUserEndpoints.test_get_user_by_id_as_admin _____
E   asyncpg.exceptions._base.InterfaceError: cannot perform operation: another operation is in progress

The above exception was the direct cause of the following exception:
E   sqlalchemy.dialects.postgresql.asyncpg.AsyncAdapt_asyncpg_dbapi.InterfaceError: <class 'asyncpg.exceptions._base.InterfaceError'>: cannot perform operation: another operation is in progress

The above exception was the direct cause of the following exception:
E   sqlalchemy.exc.InterfaceError: (sqlalchemy.dialects.postgresql.asyncpg.InterfaceError) <class 'asyncpg.exceptions._base.InterfaceError'>: cannot perform operation: another operation is in progress
    [SQL: SELECT users.id, users.email, users.hashed_password, users.username, users.full_name, users.is_active, users.is_superuser, users.is_verified, users.password_reset_token, users.password_reset_at, users.email_verification_token, users.email_verified_at, users.last_login_at, users.login_count, users.created_at, users.updated_at 
    FROM users 
    WHERE users.is_superuser = true]
    (Background on this error at: https://sqlalche.me/e/20/rvf5)
---------------------------- Captured stdout setup -----------------------------
ðŸš€ Starting StackWizard Backend...
2025-08-19 14:48:26,065 INFO sqlalchemy.engine.Engine BEGIN (implicit)
2025-08-19 14:48:26,065 INFO sqlalchemy.engine.Engine SELECT users.id, users.email, users.hashed_password, users.username, users.full_name, users.is_active, users.is_superuser, users.is_verified, users.password_reset_token, users.password_reset_at, users.email_verification_token, users.email_verified_at, users.last_login_at, users.login_count, users.created_at, users.updated_at 
FROM users 
WHERE users.is_superuser = true
2025-08-19 14:48:26,065 INFO sqlalchemy.engine.Engine [cached since 4.531s ago] ()
2025-08-19 14:48:26,065 INFO sqlalchemy.engine.Engine ROLLBACK
------------------------------ Captured log setup ------------------------------
INFO     sqlalchemy.engine.Engine:base.py:2689 BEGIN (implicit)
INFO     sqlalchemy.engine.Engine:base.py:1848 SELECT users.id, users.email, users.hashed_password, users.username, users.full_name, users.is_active, users.is_superuser, users.is_verified, users.password_reset_token, users.password_reset_at, users.email_verification_token, users.email_verified_at, users.last_login_at, users.login_count, users.created_at, users.updated_at 
FROM users 
WHERE users.is_superuser = true
INFO     sqlalchemy.engine.Engine:base.py:1848 [cached since 4.531s ago] ()
INFO     sqlalchemy.engine.Engine:base.py:2692 ROLLBACK
____ ERROR at setup of TestAdminUserEndpoints.test_get_user_by_id_not_found ____
E   asyncpg.exceptions._base.InterfaceError: cannot perform operation: another operation is in progress

The above exception was the direct cause of the following exception:
E   sqlalchemy.dialects.postgresql.asyncpg.AsyncAdapt_asyncpg_dbapi.InterfaceError: <class 'asyncpg.exceptions._base.InterfaceError'>: cannot perform operation: another operation is in progress

The above exception was the direct cause of the following exception:
E   sqlalchemy.exc.InterfaceError: (sqlalchemy.dialects.postgresql.asyncpg.InterfaceError) <class 'asyncpg.exceptions._base.InterfaceError'>: cannot perform operation: another operation is in progress
    [SQL: SELECT users.id, users.email, users.hashed_password, users.username, users.full_name, users.is_active, users.is_superuser, users.is_verified, users.password_reset_token, users.password_reset_at, users.email_verification_token, users.email_verified_at, users.last_login_at, users.login_count, users.created_at, users.updated_at 
    FROM users 
    WHERE users.is_superuser = true]
    (Background on this error at: https://sqlalche.me/e/20/rvf5)
---------------------------- Captured stdout setup -----------------------------
ðŸš€ Starting StackWizard Backend...
2025-08-19 14:48:26,091 INFO sqlalchemy.engine.Engine BEGIN (implicit)
2025-08-19 14:48:26,091 INFO sqlalchemy.engine.Engine SELECT users.id, users.email, users.hashed_password, users.username, users.full_name, users.is_active, users.is_superuser, users.is_verified, users.password_reset_token, users.password_reset_at, users.email_verification_token, users.email_verified_at, users.last_login_at, users.login_count, users.created_at, users.updated_at 
FROM users 
WHERE users.is_superuser = true
2025-08-19 14:48:26,091 INFO sqlalchemy.engine.Engine [cached since 4.557s ago] ()
2025-08-19 14:48:26,091 INFO sqlalchemy.engine.Engine ROLLBACK
------------------------------ Captured log setup ------------------------------
INFO     sqlalchemy.engine.Engine:base.py:2689 BEGIN (implicit)
INFO     sqlalchemy.engine.Engine:base.py:1848 SELECT users.id, users.email, users.hashed_password, users.username, users.full_name, users.is_active, users.is_superuser, users.is_verified, users.password_reset_token, users.password_reset_at, users.email_verification_token, users.email_verified_at, users.last_login_at, users.login_count, users.created_at, users.updated_at 
FROM users 
WHERE users.is_superuser = true
INFO     sqlalchemy.engine.Engine:base.py:1848 [cached since 4.557s ago] ()
INFO     sqlalchemy.engine.Engine:base.py:2692 ROLLBACK
______ ERROR at setup of TestAdminUserEndpoints.test_update_user_by_admin ______
E   asyncpg.exceptions._base.InterfaceError: cannot perform operation: another operation is in progress

The above exception was the direct cause of the following exception:
E   sqlalchemy.dialects.postgresql.asyncpg.AsyncAdapt_asyncpg_dbapi.InterfaceError: <class 'asyncpg.exceptions._base.InterfaceError'>: cannot perform operation: another operation is in progress

The above exception was the direct cause of the following exception:
E   sqlalchemy.exc.InterfaceError: (sqlalchemy.dialects.postgresql.asyncpg.InterfaceError) <class 'asyncpg.exceptions._base.InterfaceError'>: cannot perform operation: another operation is in progress
    [SQL: SELECT users.id, users.email, users.hashed_password, users.username, users.full_name, users.is_active, users.is_superuser, users.is_verified, users.password_reset_token, users.password_reset_at, users.email_verification_token, users.email_verified_at, users.last_login_at, users.login_count, users.created_at, users.updated_at 
    FROM users 
    WHERE users.is_superuser = true]
    (Background on this error at: https://sqlalche.me/e/20/rvf5)
---------------------------- Captured stdout setup -----------------------------
ðŸš€ Starting StackWizard Backend...
2025-08-19 14:48:26,117 INFO sqlalchemy.engine.Engine BEGIN (implicit)
2025-08-19 14:48:26,117 INFO sqlalchemy.engine.Engine SELECT users.id, users.email, users.hashed_password, users.username, users.full_name, users.is_active, users.is_superuser, users.is_verified, users.password_reset_token, users.password_reset_at, users.email_verification_token, users.email_verified_at, users.last_login_at, users.login_count, users.created_at, users.updated_at 
FROM users 
WHERE users.is_superuser = true
2025-08-19 14:48:26,117 INFO sqlalchemy.engine.Engine [cached since 4.583s ago] ()
2025-08-19 14:48:26,118 INFO sqlalchemy.engine.Engine ROLLBACK
------------------------------ Captured log setup ------------------------------
INFO     sqlalchemy.engine.Engine:base.py:2689 BEGIN (implicit)
INFO     sqlalchemy.engine.Engine:base.py:1848 SELECT users.id, users.email, users.hashed_password, users.username, users.full_name, users.is_active, users.is_superuser, users.is_verified, users.password_reset_token, users.password_reset_at, users.email_verification_token, users.email_verified_at, users.last_login_at, users.login_count, users.created_at, users.updated_at 
FROM users 
WHERE users.is_superuser = true
INFO     sqlalchemy.engine.Engine:base.py:1848 [cached since 4.583s ago] ()
INFO     sqlalchemy.engine.Engine:base.py:2692 ROLLBACK
___ ERROR at setup of TestAdminUserEndpoints.test_update_user_make_superuser ___
E   asyncpg.exceptions._base.InterfaceError: cannot perform operation: another operation is in progress

The above exception was the direct cause of the following exception:
E   sqlalchemy.dialects.postgresql.asyncpg.AsyncAdapt_asyncpg_dbapi.InterfaceError: <class 'asyncpg.exceptions._base.InterfaceError'>: cannot perform operation: another operation is in progress

The above exception was the direct cause of the following exception:
E   sqlalchemy.exc.InterfaceError: (sqlalchemy.dialects.postgresql.asyncpg.InterfaceError) <class 'asyncpg.exceptions._base.InterfaceError'>: cannot perform operation: another operation is in progress
    [SQL: SELECT users.id, users.email, users.hashed_password, users.username, users.full_name, users.is_active, users.is_superuser, users.is_verified, users.password_reset_token, users.password_reset_at, users.email_verification_token, users.email_verified_at, users.last_login_at, users.login_count, users.created_at, users.updated_at 
    FROM users 
    WHERE users.is_superuser = true]
    (Background on this error at: https://sqlalche.me/e/20/rvf5)
---------------------------- Captured stdout setup -----------------------------
ðŸš€ Starting StackWizard Backend...
2025-08-19 14:48:26,144 INFO sqlalchemy.engine.Engine BEGIN (implicit)
2025-08-19 14:48:26,144 INFO sqlalchemy.engine.Engine SELECT users.id, users.email, users.hashed_password, users.username, users.full_name, users.is_active, users.is_superuser, users.is_verified, users.password_reset_token, users.password_reset_at, users.email_verification_token, users.email_verified_at, users.last_login_at, users.login_count, users.created_at, users.updated_at 
FROM users 
WHERE users.is_superuser = true
2025-08-19 14:48:26,144 INFO sqlalchemy.engine.Engine [cached since 4.61s ago] ()
2025-08-19 14:48:26,144 INFO sqlalchemy.engine.Engine ROLLBACK
------------------------------ Captured log setup ------------------------------
INFO     sqlalchemy.engine.Engine:base.py:2689 BEGIN (implicit)
INFO     sqlalchemy.engine.Engine:base.py:1848 SELECT users.id, users.email, users.hashed_password, users.username, users.full_name, users.is_active, users.is_superuser, users.is_verified, users.password_reset_token, users.password_reset_at, users.email_verification_token, users.email_verified_at, users.last_login_at, users.login_count, users.created_at, users.updated_at 
FROM users 
WHERE users.is_superuser = true
INFO     sqlalchemy.engine.Engine:base.py:1848 [cached since 4.61s ago] ()
INFO     sqlalchemy.engine.Engine:base.py:2692 ROLLBACK
______ ERROR at setup of TestAdminUserEndpoints.test_delete_user_by_admin ______
E   asyncpg.exceptions._base.InterfaceError: cannot perform operation: another operation is in progress

The above exception was the direct cause of the following exception:
E   sqlalchemy.dialects.postgresql.asyncpg.AsyncAdapt_asyncpg_dbapi.InterfaceError: <class 'asyncpg.exceptions._base.InterfaceError'>: cannot perform operation: another operation is in progress

The above exception was the direct cause of the following exception:
E   sqlalchemy.exc.InterfaceError: (sqlalchemy.dialects.postgresql.asyncpg.InterfaceError) <class 'asyncpg.exceptions._base.InterfaceError'>: cannot perform operation: another operation is in progress
    [SQL: SELECT users.id, users.email, users.hashed_password, users.username, users.full_name, users.is_active, users.is_superuser, users.is_verified, users.password_reset_token, users.password_reset_at, users.email_verification_token, users.email_verified_at, users.last_login_at, users.login_count, users.created_at, users.updated_at 
    FROM users 
    WHERE users.is_superuser = true]
    (Background on this error at: https://sqlalche.me/e/20/rvf5)
---------------------------- Captured stdout setup -----------------------------
ðŸš€ Starting StackWizard Backend...
2025-08-19 14:48:26,171 INFO sqlalchemy.engine.Engine BEGIN (implicit)
2025-08-19 14:48:26,171 INFO sqlalchemy.engine.Engine SELECT users.id, users.email, users.hashed_password, users.username, users.full_name, users.is_active, users.is_superuser, users.is_verified, users.password_reset_token, users.password_reset_at, users.email_verification_token, users.email_verified_at, users.last_login_at, users.login_count, users.created_at, users.updated_at 
FROM users 
WHERE users.is_superuser = true
2025-08-19 14:48:26,171 INFO sqlalchemy.engine.Engine [cached since 4.637s ago] ()
2025-08-19 14:48:26,171 INFO sqlalchemy.engine.Engine ROLLBACK
------------------------------ Captured log setup ------------------------------
INFO     sqlalchemy.engine.Engine:base.py:2689 BEGIN (implicit)
INFO     sqlalchemy.engine.Engine:base.py:1848 SELECT users.id, users.email, users.hashed_password, users.username, users.full_name, users.is_active, users.is_superuser, users.is_verified, users.password_reset_token, users.password_reset_at, users.email_verification_token, users.email_verified_at, users.last_login_at, users.login_count, users.created_at, users.updated_at 
FROM users 
WHERE users.is_superuser = true
INFO     sqlalchemy.engine.Engine:base.py:1848 [cached since 4.637s ago] ()
INFO     sqlalchemy.engine.Engine:base.py:2692 ROLLBACK
______ ERROR at setup of TestAdminUserEndpoints.test_create_user_by_admin ______
E   asyncpg.exceptions._base.InterfaceError: cannot perform operation: another operation is in progress

The above exception was the direct cause of the following exception:
E   sqlalchemy.dialects.postgresql.asyncpg.AsyncAdapt_asyncpg_dbapi.InterfaceError: <class 'asyncpg.exceptions._base.InterfaceError'>: cannot perform operation: another operation is in progress

The above exception was the direct cause of the following exception:
E   sqlalchemy.exc.InterfaceError: (sqlalchemy.dialects.postgresql.asyncpg.InterfaceError) <class 'asyncpg.exceptions._base.InterfaceError'>: cannot perform operation: another operation is in progress
    [SQL: SELECT users.id, users.email, users.hashed_password, users.username, users.full_name, users.is_active, users.is_superuser, users.is_verified, users.password_reset_token, users.password_reset_at, users.email_verification_token, users.email_verified_at, users.last_login_at, users.login_count, users.created_at, users.updated_at 
    FROM users 
    WHERE users.is_superuser = true]
    (Background on this error at: https://sqlalche.me/e/20/rvf5)
---------------------------- Captured stdout setup -----------------------------
ðŸš€ Starting StackWizard Backend...
2025-08-19 14:48:26,200 INFO sqlalchemy.engine.Engine BEGIN (implicit)
2025-08-19 14:48:26,200 INFO sqlalchemy.engine.Engine SELECT users.id, users.email, users.hashed_password, users.username, users.full_name, users.is_active, users.is_superuser, users.is_verified, users.password_reset_token, users.password_reset_at, users.email_verification_token, users.email_verified_at, users.last_login_at, users.login_count, users.created_at, users.updated_at 
FROM users 
WHERE users.is_superuser = true
2025-08-19 14:48:26,200 INFO sqlalchemy.engine.Engine [cached since 4.666s ago] ()
2025-08-19 14:48:26,200 INFO sqlalchemy.engine.Engine ROLLBACK
------------------------------ Captured log setup ------------------------------
INFO     sqlalchemy.engine.Engine:base.py:2689 BEGIN (implicit)
INFO     sqlalchemy.engine.Engine:base.py:1848 SELECT users.id, users.email, users.hashed_password, users.username, users.full_name, users.is_active, users.is_superuser, users.is_verified, users.password_reset_token, users.password_reset_at, users.email_verification_token, users.email_verified_at, users.last_login_at, users.login_count, users.created_at, users.updated_at 
FROM users 
WHERE users.is_superuser = true
INFO     sqlalchemy.engine.Engine:base.py:1848 [cached since 4.666s ago] ()
INFO     sqlalchemy.engine.Engine:base.py:2692 ROLLBACK
______ ERROR at setup of TestPasswordRecovery.test_request_password_reset ______
E   asyncpg.exceptions._base.InterfaceError: cannot perform operation: another operation is in progress

The above exception was the direct cause of the following exception:
E   sqlalchemy.dialects.postgresql.asyncpg.AsyncAdapt_asyncpg_dbapi.InterfaceError: <class 'asyncpg.exceptions._base.InterfaceError'>: cannot perform operation: another operation is in progress

The above exception was the direct cause of the following exception:
E   sqlalchemy.exc.InterfaceError: (sqlalchemy.dialects.postgresql.asyncpg.InterfaceError) <class 'asyncpg.exceptions._base.InterfaceError'>: cannot perform operation: another operation is in progress
    [SQL: SELECT users.id, users.email, users.hashed_password, users.username, users.full_name, users.is_active, users.is_superuser, users.is_verified, users.password_reset_token, users.password_reset_at, users.email_verification_token, users.email_verified_at, users.last_login_at, users.login_count, users.created_at, users.updated_at 
    FROM users 
    WHERE users.is_superuser = true]
    (Background on this error at: https://sqlalche.me/e/20/rvf5)
---------------------------- Captured stdout setup -----------------------------
ðŸš€ Starting StackWizard Backend...
2025-08-19 14:48:26,228 INFO sqlalchemy.engine.Engine BEGIN (implicit)
2025-08-19 14:48:26,228 INFO sqlalchemy.engine.Engine SELECT users.id, users.email, users.hashed_password, users.username, users.full_name, users.is_active, users.is_superuser, users.is_verified, users.password_reset_token, users.password_reset_at, users.email_verification_token, users.email_verified_at, users.last_login_at, users.login_count, users.created_at, users.updated_at 
FROM users 
WHERE users.is_superuser = true
2025-08-19 14:48:26,228 INFO sqlalchemy.engine.Engine [cached since 4.694s ago] ()
2025-08-19 14:48:26,228 INFO sqlalchemy.engine.Engine ROLLBACK
------------------------------ Captured log setup ------------------------------
INFO     sqlalchemy.engine.Engine:base.py:2689 BEGIN (implicit)
INFO     sqlalchemy.engine.Engine:base.py:1848 SELECT users.id, users.email, users.hashed_password, users.username, users.full_name, users.is_active, users.is_superuser, users.is_verified, users.password_reset_token, users.password_reset_at, users.email_verification_token, users.email_verified_at, users.last_login_at, users.login_count, users.created_at, users.updated_at 
FROM users 
WHERE users.is_superuser = true
INFO     sqlalchemy.engine.Engine:base.py:1848 [cached since 4.694s ago] ()
INFO     sqlalchemy.engine.Engine:base.py:2692 ROLLBACK
_ ERROR at setup of TestPasswordRecovery.test_request_password_reset_nonexistent_email _
E   asyncpg.exceptions._base.InterfaceError: cannot perform operation: another operation is in progress

The above exception was the direct cause of the following exception:
E   sqlalchemy.dialects.postgresql.asyncpg.AsyncAdapt_asyncpg_dbapi.InterfaceError: <class 'asyncpg.exceptions._base.InterfaceError'>: cannot perform operation: another operation is in progress

The above exception was the direct cause of the following exception:
E   sqlalchemy.exc.InterfaceError: (sqlalchemy.dialects.postgresql.asyncpg.InterfaceError) <class 'asyncpg.exceptions._base.InterfaceError'>: cannot perform operation: another operation is in progress
    [SQL: SELECT users.id, users.email, users.hashed_password, users.username, users.full_name, users.is_active, users.is_superuser, users.is_verified, users.password_reset_token, users.password_reset_at, users.email_verification_token, users.email_verified_at, users.last_login_at, users.login_count, users.created_at, users.updated_at 
    FROM users 
    WHERE users.is_superuser = true]
    (Background on this error at: https://sqlalche.me/e/20/rvf5)
---------------------------- Captured stdout setup -----------------------------
ðŸš€ Starting StackWizard Backend...
2025-08-19 14:48:26,255 INFO sqlalchemy.engine.Engine BEGIN (implicit)
2025-08-19 14:48:26,255 INFO sqlalchemy.engine.Engine SELECT users.id, users.email, users.hashed_password, users.username, users.full_name, users.is_active, users.is_superuser, users.is_verified, users.password_reset_token, users.password_reset_at, users.email_verification_token, users.email_verified_at, users.last_login_at, users.login_count, users.created_at, users.updated_at 
FROM users 
WHERE users.is_superuser = true
2025-08-19 14:48:26,255 INFO sqlalchemy.engine.Engine [cached since 4.721s ago] ()
2025-08-19 14:48:26,256 INFO sqlalchemy.engine.Engine ROLLBACK
------------------------------ Captured log setup ------------------------------
INFO     sqlalchemy.engine.Engine:base.py:2689 BEGIN (implicit)
INFO     sqlalchemy.engine.Engine:base.py:1848 SELECT users.id, users.email, users.hashed_password, users.username, users.full_name, users.is_active, users.is_superuser, users.is_verified, users.password_reset_token, users.password_reset_at, users.email_verification_token, users.email_verified_at, users.last_login_at, users.login_count, users.created_at, users.updated_at 
FROM users 
WHERE users.is_superuser = true
INFO     sqlalchemy.engine.Engine:base.py:1848 [cached since 4.721s ago] ()
INFO     sqlalchemy.engine.Engine:base.py:2692 ROLLBACK
____ ERROR at setup of TestPasswordRecovery.test_reset_password_with_token _____
E   asyncpg.exceptions._base.InterfaceError: cannot perform operation: another operation is in progress

The above exception was the direct cause of the following exception:
E   sqlalchemy.dialects.postgresql.asyncpg.AsyncAdapt_asyncpg_dbapi.InterfaceError: <class 'asyncpg.exceptions._base.InterfaceError'>: cannot perform operation: another operation is in progress

The above exception was the direct cause of the following exception:
E   sqlalchemy.exc.InterfaceError: (sqlalchemy.dialects.postgresql.asyncpg.InterfaceError) <class 'asyncpg.exceptions._base.InterfaceError'>: cannot perform operation: another operation is in progress
    [SQL: SELECT users.id, users.email, users.hashed_password, users.username, users.full_name, users.is_active, users.is_superuser, users.is_verified, users.password_reset_token, users.password_reset_at, users.email_verification_token, users.email_verified_at, users.last_login_at, users.login_count, users.created_at, users.updated_at 
    FROM users 
    WHERE users.is_superuser = true]
    (Background on this error at: https://sqlalche.me/e/20/rvf5)
---------------------------- Captured stdout setup -----------------------------
ðŸš€ Starting StackWizard Backend...
2025-08-19 14:48:26,282 INFO sqlalchemy.engine.Engine BEGIN (implicit)
2025-08-19 14:48:26,282 INFO sqlalchemy.engine.Engine SELECT users.id, users.email, users.hashed_password, users.username, users.full_name, users.is_active, users.is_superuser, users.is_verified, users.password_reset_token, users.password_reset_at, users.email_verification_token, users.email_verified_at, users.last_login_at, users.login_count, users.created_at, users.updated_at 
FROM users 
WHERE users.is_superuser = true
2025-08-19 14:48:26,282 INFO sqlalchemy.engine.Engine [cached since 4.748s ago] ()
2025-08-19 14:48:26,282 INFO sqlalchemy.engine.Engine ROLLBACK
------------------------------ Captured log setup ------------------------------
INFO     sqlalchemy.engine.Engine:base.py:2689 BEGIN (implicit)
INFO     sqlalchemy.engine.Engine:base.py:1848 SELECT users.id, users.email, users.hashed_password, users.username, users.full_name, users.is_active, users.is_superuser, users.is_verified, users.password_reset_token, users.password_reset_at, users.email_verification_token, users.email_verified_at, users.last_login_at, users.login_count, users.created_at, users.updated_at 
FROM users 
WHERE users.is_superuser = true
INFO     sqlalchemy.engine.Engine:base.py:1848 [cached since 4.748s ago] ()
INFO     sqlalchemy.engine.Engine:base.py:2692 ROLLBACK
___ ERROR at setup of TestPasswordRecovery.test_reset_password_invalid_token ___
E   asyncpg.exceptions._base.InterfaceError: cannot perform operation: another operation is in progress

The above exception was the direct cause of the following exception:
E   sqlalchemy.dialects.postgresql.asyncpg.AsyncAdapt_asyncpg_dbapi.InterfaceError: <class 'asyncpg.exceptions._base.InterfaceError'>: cannot perform operation: another operation is in progress

The above exception was the direct cause of the following exception:
E   sqlalchemy.exc.InterfaceError: (sqlalchemy.dialects.postgresql.asyncpg.InterfaceError) <class 'asyncpg.exceptions._base.InterfaceError'>: cannot perform operation: another operation is in progress
    [SQL: SELECT users.id, users.email, users.hashed_password, users.username, users.full_name, users.is_active, users.is_superuser, users.is_verified, users.password_reset_token, users.password_reset_at, users.email_verification_token, users.email_verified_at, users.last_login_at, users.login_count, users.created_at, users.updated_at 
    FROM users 
    WHERE users.is_superuser = true]
    (Background on this error at: https://sqlalche.me/e/20/rvf5)
---------------------------- Captured stdout setup -----------------------------
ðŸš€ Starting StackWizard Backend...
2025-08-19 14:48:26,309 INFO sqlalchemy.engine.Engine BEGIN (implicit)
2025-08-19 14:48:26,309 INFO sqlalchemy.engine.Engine SELECT users.id, users.email, users.hashed_password, users.username, users.full_name, users.is_active, users.is_superuser, users.is_verified, users.password_reset_token, users.password_reset_at, users.email_verification_token, users.email_verified_at, users.last_login_at, users.login_count, users.created_at, users.updated_at 
FROM users 
WHERE users.is_superuser = true
2025-08-19 14:48:26,309 INFO sqlalchemy.engine.Engine [cached since 4.775s ago] ()
2025-08-19 14:48:26,310 INFO sqlalchemy.engine.Engine ROLLBACK
------------------------------ Captured log setup ------------------------------
INFO     sqlalchemy.engine.Engine:base.py:2689 BEGIN (implicit)
INFO     sqlalchemy.engine.Engine:base.py:1848 SELECT users.id, users.email, users.hashed_password, users.username, users.full_name, users.is_active, users.is_superuser, users.is_verified, users.password_reset_token, users.password_reset_at, users.email_verification_token, users.email_verified_at, users.last_login_at, users.login_count, users.created_at, users.updated_at 
FROM users 
WHERE users.is_superuser = true
INFO     sqlalchemy.engine.Engine:base.py:1848 [cached since 4.775s ago] ()
INFO     sqlalchemy.engine.Engine:base.py:2692 ROLLBACK
=================================== FAILURES ===================================
/Users/rafal.lagowski/ProjectsRL/gen-projects/project-generator-cli/templates/common/backend/tests/test_admin.py:32: assert 404 == 200
/Users/rafal.lagowski/ProjectsRL/gen-projects/project-generator-cli/templates/common/backend/tests/test_auth.py:109: assert 8999.726318 < 1900
/Users/rafal.lagowski/ProjectsRL/gen-projects/project-generator-cli/templates/common/backend/tests/test_auth.py:114: NameError: name 'create_refresh_token' is not defined
/Users/rafal.lagowski/ProjectsRL/gen-projects/project-generator-cli/templates/common/backend/tests/test_auth.py:137: AssertionError: assert None == 'test-user-id'
/Users/rafal.lagowski/ProjectsRL/gen-projects/project-generator-cli/templates/common/backend/venv/lib/python3.11/site-packages/pydantic/main.py:761: AttributeError: 'UserUpdate' object has no attribute 'is_verified'
/Users/rafal.lagowski/ProjectsRL/gen-projects/project-generator-cli/templates/common/backend/venv/lib/python3.11/site-packages/pydantic/main.py:761: AttributeError: 'TokenData' object has no attribute 'sub'
/Users/rafal.lagowski/ProjectsRL/gen-projects/project-generator-cli/templates/common/backend/tests/test_schemas.py:192: pydantic_core._pydantic_core.ValidationError: 2 validation errors for PasswordReset
=============================== warnings summary ===============================
app/core/config.py:34
  /Users/rafal.lagowski/ProjectsRL/gen-projects/project-generator-cli/templates/common/backend/tests/../app/core/config.py:34: PydanticDeprecatedSince20: Pydantic V1 style `@validator` validators are deprecated. You should migrate to Pydantic V2 style `@field_validator` validators, see the migration guide for more details. Deprecated in Pydantic V2.0 to be removed in V3.0. See Pydantic V2 Migration Guide at https://errors.pydantic.dev/2.5/migration/
    @validator("BACKEND_CORS_ORIGINS", pre=True)

venv/lib/python3.11/site-packages/pydantic/_internal/_config.py:268
venv/lib/python3.11/site-packages/pydantic/_internal/_config.py:268
venv/lib/python3.11/site-packages/pydantic/_internal/_config.py:268
  /Users/rafal.lagowski/ProjectsRL/gen-projects/project-generator-cli/templates/common/backend/venv/lib/python3.11/site-packages/pydantic/_internal/_config.py:268: PydanticDeprecatedSince20: Support for class-based `config` is deprecated, use ConfigDict instead. Deprecated in Pydantic V2.0 to be removed in V3.0. See Pydantic V2 Migration Guide at https://errors.pydantic.dev/2.5/migration/
    warnings.warn(DEPRECATION_MESSAGE, DeprecationWarning)

venv/lib/python3.11/site-packages/passlib/utils/__init__.py:854
  /Users/rafal.lagowski/ProjectsRL/gen-projects/project-generator-cli/templates/common/backend/venv/lib/python3.11/site-packages/passlib/utils/__init__.py:854: DeprecationWarning: 'crypt' is deprecated and slated for removal in Python 3.13
    from crypt import crypt as _crypt

app/schemas/user.py:21
  /Users/rafal.lagowski/ProjectsRL/gen-projects/project-generator-cli/templates/common/backend/tests/../app/schemas/user.py:21: PydanticDeprecatedSince20: Pydantic V1 style `@validator` validators are deprecated. You should migrate to Pydantic V2 style `@field_validator` validators, see the migration guide for more details. Deprecated in Pydantic V2.0 to be removed in V3.0. See Pydantic V2 Migration Guide at https://errors.pydantic.dev/2.5/migration/
    @validator('password')

app/schemas/user.py:47
  /Users/rafal.lagowski/ProjectsRL/gen-projects/project-generator-cli/templates/common/backend/tests/../app/schemas/user.py:47: PydanticDeprecatedSince20: Pydantic V1 style `@validator` validators are deprecated. You should migrate to Pydantic V2 style `@field_validator` validators, see the migration guide for more details. Deprecated in Pydantic V2.0 to be removed in V3.0. See Pydantic V2 Migration Guide at https://errors.pydantic.dev/2.5/migration/
    @validator('new_password')

app/schemas/user.py:109
  /Users/rafal.lagowski/ProjectsRL/gen-projects/project-generator-cli/templates/common/backend/tests/../app/schemas/user.py:109: PydanticDeprecatedSince20: Pydantic V1 style `@validator` validators are deprecated. You should migrate to Pydantic V2 style `@field_validator` validators, see the migration guide for more details. Deprecated in Pydantic V2.0 to be removed in V3.0. See Pydantic V2 Migration Guide at https://errors.pydantic.dev/2.5/migration/
    @validator('username', pre=True)

app/schemas/user.py:117
  /Users/rafal.lagowski/ProjectsRL/gen-projects/project-generator-cli/templates/common/backend/tests/../app/schemas/user.py:117: PydanticDeprecatedSince20: Pydantic V1 style `@validator` validators are deprecated. You should migrate to Pydantic V2 style `@field_validator` validators, see the migration guide for more details. Deprecated in Pydantic V2.0 to be removed in V3.0. See Pydantic V2 Migration Guide at https://errors.pydantic.dev/2.5/migration/
    @validator('password')

app/schemas/user.py:137
  /Users/rafal.lagowski/ProjectsRL/gen-projects/project-generator-cli/templates/common/backend/tests/../app/schemas/user.py:137: PydanticDeprecatedSince20: Pydantic V1 style `@validator` validators are deprecated. You should migrate to Pydantic V2 style `@field_validator` validators, see the migration guide for more details. Deprecated in Pydantic V2.0 to be removed in V3.0. See Pydantic V2 Migration Guide at https://errors.pydantic.dev/2.5/migration/
    @validator('new_password')

tests/test_auth.py::TestAuthentication::test_authenticate_valid_user
tests/test_auth.py::TestAuthentication::test_authenticate_invalid_password
tests/test_auth.py::TestAuthentication::test_authenticate_nonexistent_user
tests/test_auth.py::TestAuthentication::test_authenticate_inactive_user
tests/test_auth.py::TestAuthentication::test_authenticate_updates_login_tracking
  /Users/rafal.lagowski/ProjectsRL/gen-projects/project-generator-cli/templates/common/backend/venv/lib/python3.11/site-packages/_pytest/python.py:183: PytestUnhandledCoroutineWarning: async def functions are not natively supported and have been skipped.
  You need to install a suitable plugin for your async framework, for example:
    - anyio
    - pytest-asyncio
    - pytest-tornasync
    - pytest-trio
    - pytest-twisted
    warnings.warn(PytestUnhandledCoroutineWarning(msg.format(nodeid)))

-- Docs: https://docs.pytest.org/en/stable/how-to/capture-warnings.html
=========================== short test summary info ============================
SKIPPED [5] venv/lib/python3.11/site-packages/_pytest/python.py:184: async def function and no async plugin installed (see warnings)
ERROR tests/test_admin.py::TestAdminDashboard::test_get_system_stats_as_regular_user
ERROR tests/test_admin.py::TestAdminDashboard::test_get_recent_registrations
ERROR tests/test_admin.py::TestAdminDashboard::test_search_users_by_email - s...
ERROR tests/test_admin.py::TestAdminDashboard::test_bulk_activate_users - sql...
ERROR tests/test_admin.py::TestAdminDashboard::test_bulk_deactivate_users - s...
ERROR tests/test_admin.py::TestAdminAuditLog::test_log_admin_action - sqlalch...
ERROR tests/test_admin.py::TestAdminAuditLog::test_audit_log_access_denied_for_regular_user
ERROR tests/test_admin.py::TestAdminUserManagement::test_admin_reset_user_password
ERROR tests/test_admin.py::TestAdminUserManagement::test_admin_verify_user_email
ERROR tests/test_admin.py::TestAdminUserManagement::test_admin_export_users
ERROR tests/test_admin.py::TestAdminUserManagement::test_admin_import_users
ERROR tests/test_admin.py::TestAdminUserManagement::test_admin_get_user_sessions
ERROR tests/test_admin.py::TestAdminUserManagement::test_admin_revoke_user_sessions
ERROR tests/test_auth.py::TestAuthEndpoints::test_login_endpoint_success - sq...
ERROR tests/test_auth.py::TestAuthEndpoints::test_login_endpoint_invalid_password
ERROR tests/test_auth.py::TestAuthEndpoints::test_login_endpoint_nonexistent_user
ERROR tests/test_auth.py::TestAuthEndpoints::test_register_endpoint_success
ERROR tests/test_auth.py::TestAuthEndpoints::test_register_endpoint_duplicate_email
ERROR tests/test_auth.py::TestAuthEndpoints::test_register_endpoint_weak_password
ERROR tests/test_auth.py::TestAuthEndpoints::test_refresh_token_endpoint - sq...
ERROR tests/test_auth.py::TestAuthEndpoints::test_refresh_token_invalid - sql...
ERROR tests/test_users.py::TestUserEndpoints::test_get_current_user - sqlalch...
ERROR tests/test_users.py::TestUserEndpoints::test_get_current_user_unauthorized
ERROR tests/test_users.py::TestUserEndpoints::test_get_current_user_invalid_token
ERROR tests/test_users.py::TestUserEndpoints::test_update_current_user - sqla...
ERROR tests/test_users.py::TestUserEndpoints::test_update_current_user_duplicate_email
ERROR tests/test_users.py::TestUserEndpoints::test_update_user_password - sql...
ERROR tests/test_users.py::TestUserEndpoints::test_update_password_wrong_current
ERROR tests/test_users.py::TestUserEndpoints::test_delete_current_user - sqla...
ERROR tests/test_users.py::TestAdminUserEndpoints::test_get_all_users_as_admin
ERROR tests/test_users.py::TestAdminUserEndpoints::test_get_all_users_as_regular_user
ERROR tests/test_users.py::TestAdminUserEndpoints::test_get_all_users_with_pagination
ERROR tests/test_users.py::TestAdminUserEndpoints::test_get_user_by_id_as_admin
ERROR tests/test_users.py::TestAdminUserEndpoints::test_get_user_by_id_not_found
ERROR tests/test_users.py::TestAdminUserEndpoints::test_update_user_by_admin
ERROR tests/test_users.py::TestAdminUserEndpoints::test_update_user_make_superuser
ERROR tests/test_users.py::TestAdminUserEndpoints::test_delete_user_by_admin
ERROR tests/test_users.py::TestAdminUserEndpoints::test_create_user_by_admin
ERROR tests/test_users.py::TestPasswordRecovery::test_request_password_reset
ERROR tests/test_users.py::TestPasswordRecovery::test_request_password_reset_nonexistent_email
ERROR tests/test_users.py::TestPasswordRecovery::test_reset_password_with_token
ERROR tests/test_users.py::TestPasswordRecovery::test_reset_password_invalid_token
FAILED tests/test_admin.py::TestAdminDashboard::test_get_system_stats_as_admin
FAILED tests/test_auth.py::TestJWTTokens::test_access_token_expiration - asse...
FAILED tests/test_auth.py::TestJWTTokens::test_refresh_token_longer_expiration
FAILED tests/test_auth.py::TestJWTTokens::test_verify_valid_token - Assertion...
FAILED tests/test_schemas.py::TestUserSchemas::test_user_update_schema - Attr...
FAILED tests/test_schemas.py::TestUserSchemas::test_token_data_schema - Attri...
FAILED tests/test_schemas.py::TestUserSchemas::test_password_reset_schema - p...
======= 7 failed, 24 passed, 5 skipped, 15 warnings, 42 errors in 4.91s ========
